Workbook

Sheet LetterGrades-CSL100-Intro_Progr
A1: Vaibhav Khatri | B1: B24DS035 | C1: A- | D1: vaibhavkh@iitbhilai.ac.in | E1: 36.5 | F1: 29 | G1: =0.5*(E1+F1) -> 32.75 | H1: 15 | I1: 18 | J1: 18 | K1: =H1/4+I1/4+J1/9 -> 10.25 | L1: 80 | M1: 198 | N1: 190 | O1: =max(M1:N1) -> 198 | P1: 95 | Q1: =L1/20+O1/40+P1/20 -> 13.7 | R1: 7 | S1: 9 | T1: 7 | U1: 12 | V1: 15 | W1: 14 | X1: 20 | Y1: 29 | Z1: 29 | AA1: 30 | AB1: 30 | AC1: =SUM(R1:AB1)/20 -> 10.1 | AD1: 50 | AE1: 330 | AF1: 1 | AG1: =(AC1*AF1) -> 10.1 | AH1: =(AD1+AE1)/40 -> 9.5 | AI1: =G1+K1+Q1+AG1+AH1 -> 76.3
A2: KILAPARTHI PARVEEN SATYA TEJA | B2: B24EC013 | C2: A | D2: kilaparthipst@iitbhilai.ac.in | E2: 44 | F2: 30 | G2: =0.5*(E2+F2) -> 37 | H2: 15 | I2: 17 | J2: 24 | K2: =H2/4+I2/4+J2/9 -> 10.666667 | L2: 90 | M2: 190 | N2: 200 | O2: =max(M2:N2) -> 200 | P2: 95 | Q2: =L2/20+O2/40+P2/20 -> 14.25 | R2: 7 | S2: 6 | T2: 8 | U2: 12 | V2: 15 | W2: 15 | X2: 20 | Y2: 30 | Z2: 30 | AA2: 30 | AB2: 30 | AC2: =SUM(R2:AB2)/20 -> 10.15 | AD2: 50 | AE2: 330 | AF2: 1 | AG2: =(AC2*AF2) -> 10.15 | AH2: =(AD2+AE2)/40 -> 9.5 | AI2: =G2+K2+Q2+AG2+AH2 -> 81.566667
A3: MANEPALLI SRITEJA | B3: B24EC016 | C3: A | D3: manepallivdst@iitbhilai.ac.in | E3: 47 | F3: 34 | G3: =0.5*(E3+F3) -> 40.5 | H3: 15 | I3: 19 | J3: 26 | K3: =H3/4+I3/4+J3/9 -> 11.388889 | L3: 95 | M3: 190 | N3: 200 | O3: =max(M3:N3) -> 200 | P3: 95 | Q3: =L3/20+O3/40+P3/20 -> 14.5 | R3: 7 | S3: 7 | T3: 9 | U3: 13 | V3: 15 | W3: 15 | X3: 20 | Y3: 25 | Z3: 28 | AA3: 30 | AB3: 28 | AC3: =SUM(R3:AB3)/20 -> 9.85 | AD3: 50 | AE3: 330 | AF3: 0.5 | AG3: =(AC3*AF3) -> 4.925 | AH3: =(AD3+AE3)/40 -> 9.5 | AI3: =G3+K3+Q3+AG3+AH3 -> 80.813889
A4: SAINI AMAN | B4: B24MT001 | C4: A- | D4: 101624671656031679776 | E4: 45 | F4: 25 | G4: =0.5*(E4+F4) -> 35 | H4: 8 | I4: 18 | J4: 26 | K4: =H4/4+I4/4+J4/9 -> 9.3888889 | L4: 95 | M4: 190 | N4: 190 | O4: =max(M4:N4) -> 190 | P4: 95 | Q4: =L4/20+O4/40+P4/20 -> 14.25 | R4: 6 | U4: 12 | V4: 15 | W4: 15 | X4: 20 | Y4: 25 | Z4: 30 | AA4: 30 | AC4: =SUM(R4:AB4)/20 -> 7.65 | AD4: 50 | AE4: 330 | AF4: 1 | AG4: =(AC4*AF4) -> 7.65 | AH4: =(AD4+AE4)/40 -> 9.5 | AI4: =G4+K4+Q4+AG4+AH4 -> 75.788889
A5: Abhinav | B5: B25CS002 | C5: A | D5: abhinav@iitbhilai.ac.in | E5: =VLOOKUP(B5, 'CSE-Sandeep'!$B$2:$G$61,5) -> 45 | F5: 32 | G5: =0.5*(E5+F5) -> 38.5 | H5: 13 | I5: 13 | J5: 43 | K5: =H5/4+I5/4+J5/9 -> 11.277778 | L5: 100 | M5: 200 | O5: =max(M5:N5) -> 200 | P5: 98 | Q5: =L5/20+O5/40+P5/20 -> 14.9 | R5: 7 | S5: 8 | T5: 15 | U5: 15 | V5: 14 | W5: 15 | X5: 20 | Y5: 30 | Z5: 30 | AA5: 3 | AC5: =SUM(R5:AB5)/20 -> 7.85 | AD5: 40 | AE5: 335 | AF5: 1 | AG5: =(AC5*AF5) -> 7.85 | AH5: =(AD5+AE5)/40 -> 9.375 | AI5: =G5+K5+Q5+AG5+AH5 -> 81.902778
A6: ADHIA SOHAM | B6: B25CS003 | C6: A- | D6: adhiasoham@iitbhilai.ac.in | E6: =VLOOKUP(B6, 'CSE-Sandeep'!$B$2:$G$61,5) -> 36 | F6: 31 | G6: =0.5*(E6+F6) -> 33.5 | H6: 17 | I6: 17 | J6: 32.5 | K6: =H6/4+I6/4+J6/9 -> 12.111111 | L6: 100 | M6: 200 | O6: =max(M6:N6) -> 200 | P6: 100 | Q6: =L6/20+O6/40+P6/20 -> 15 | R6: 6 | S6: 8 | T6: 14 | U6: 10 | V6: 15 | W6: 13 | X6: 19 | Y6: 30 | Z6: 0 | AA6: 29 | AB6: 30 | AC6: =SUM(R6:AB6)/20 -> 8.7 | AD6: 50 | AE6: 340 | AF6: 1 | AG6: =(AC6*AF6) -> 8.7 | AH6: =(AD6+AE6)/40 -> 9.75 | AI6: =G6+K6+Q6+AG6+AH6 -> 79.061111
A7: ADITYA JAISWAL | B7: B25CS004 | C7: A | D7: adityajaiswal@iitbhilai.ac.in | E7: =VLOOKUP(B7, 'CSE-Sandeep'!$B$2:$G$61,5) -> 50 | F7: 35 | G7: =0.5*(E7+F7) -> 42.5 | H7: 16 | I7: 16 | J7: 45 | K7: =H7/4+I7/4+J7/9 -> 13 | L7: 90 | M7: 200 | O7: =max(M7:N7) -> 200 | P7: 100 | Q7: =L7/20+O7/40+P7/20 -> 14.5 | R7: 7 | S7: 6 | T7: 14 | U7: 0 | V7: 15 | W7: 15 | X7: 20 | Y7: 30 | Z7: 30 | AA7: 30 | AB7: 30 | AC7: =SUM(R7:AB7)/20 -> 9.85 | AD7: 30 | AE7: 335 | AF7: 1 | AG7: =(AC7*AF7) -> 9.85 | AH7: =(AD7+AE7)/40 -> 9.125 | AI7: =G7+K7+Q7+AG7+AH7 -> 88.975
A8: AKSHAT KANSAL | B8: B25CS005 | C8: B | D8: akshatkansal@iitbhilai.ac.in | E8: =VLOOKUP(B8, 'CSE-Sandeep'!$B$2:$G$61,5) -> 37 | F8: 33 | G8: =0.5*(E8+F8) -> 35 | H8: 11 | I8: 11 | J8: 32 | K8: =H8/4+I8/4+J8/9 -> 9.0555556 | L8: 100 | M8: 200 | O8: =max(M8:N8) -> 200 | P8: 85 | Q8: =L8/20+O8/40+P8/20 -> 14.25 | R8: 6 | S8: 8 | T8: 15 | U8: 10 | V8: 11 | W8: 14 | X8: 20 | Y8: 30 | Z8: 30 | AA8: 30 | AC8: =SUM(R8:AB8)/20 -> 8.7 | AD8: 50 | AE8: 340 | AF8: 0.5 | AG8: =(AC8*AF8) -> 4.35 | AH8: =(AD8+AE8)/40 -> 9.75 | AI8: =G8+K8+Q8+AG8+AH8 -> 72.405556
A9: ANKIT GYEN | B9: B25CS006 | C9: A | D9: ankitgyen@iitbhilai.ac.in | E9: =VLOOKUP(B9, 'CSE-Sandeep'!$B$2:$G$61,5) -> 46 | F9: 37 | G9: =0.5*(E9+F9) -> 41.5 | H9: 17 | I9: 17 | J9: 37 | K9: =H9/4+I9/4+J9/9 -> 12.611111 | L9: 95 | M9: 200 | O9: =max(M9:N9) -> 200 | Q9: =L9/20+O9/40+P9/20 -> 9.75 | R9: 6 | S9: 7 | T9: 15 | U9: 8 | V9: 15 | W9: 14 | X9: 20 | Y9: 30 | Z9: 0 | AA9: 30 | AC9: =SUM(R9:AB9)/20 -> 7.25 | AD9: 30 | AE9: 340 | AF9: 1 | AG9: =(AC9*AF9) -> 7.25 | AH9: =(AD9+AE9)/40 -> 9.25 | AI9: =G9+K9+Q9+AG9+AH9 -> 80.361111
A10: Anugu Raghupathi | B10: B25CS007 | C10: B- | D10: anuguraghu@iitbhilai.ac.in | E10: =VLOOKUP(B10, 'CSE-Sandeep'!$B$2:$G$61,5) -> 24 | F10: 18 | G10: =0.5*(E10+F10) -> 21 | H10: 15 | I10: 15 | J10: 35 | K10: =H10/4+I10/4+J10/9 -> 11.388889 | L10: 85 | M10: 180 | O10: =max(M10:N10) -> 180 | Q10: =L10/20+O10/40+P10/20 -> 8.75 | R10: 5 | S10: 5 | T10: 14 | U10: 10 | V10: 15 | W10: 12 | X10: 20 | Y10: 30 | Z10: 24 | AA10: 29 | AB10: 29 | AC10: =SUM(R10:AB10)/20 -> 9.65 | AD10: 40 | AE10: 340 | AF10: 1 | AG10: =(AC10*AF10) -> 9.65 | AH10: =(AD10+AE10)/40 -> 9.5 | AI10: =G10+K10+Q10+AG10+AH10 -> 60.288889
A11: ARYAMAAN SINGH | B11: B25CS008 | C11: A | D11: aryamaansingh@iitbhilai.ac.in | E11: =VLOOKUP(B11, 'CSE-Sandeep'!$B$2:$G$61,5) -> 47 | F11: 33 | G11: =0.5*(E11+F11) -> 40 | H11: 11 | I11: 11 | J11: 35.5 | K11: =H11/4+I11/4+J11/9 -> 9.4444444 | L11: 95 | M11: 190 | O11: =max(M11:N11) -> 190 | P11: 92 | Q11: =L11/20+O11/40+P11/20 -> 14.1 | R11: 6 | S11: 8 | T11: 14 | U11: 10 | V11: 15 | W11: 14 | X11: 20 | Y11: 30 | Z11: 30 | AA11: 30 | AC11: =SUM(R11:AB11)/20 -> 8.85 | AD11: 50 | AE11: 330 | AF11: 1 | AG11: =(AC11*AF11) -> 8.85 | AH11: =(AD11+AE11)/40 -> 9.5 | AI11: =G11+K11+Q11+AG11+AH11 -> 81.894444
A12: ARYAN DESHMUKH | B12: B25CS009 | C12: A | D12: aryanmanish@iitbhilai.ac.in | E12: =VLOOKUP(B12, 'CSE-Sandeep'!$B$2:$G$61,5) -> 40 | F12: 35 | G12: =0.5*(E12+F12) -> 37.5 | H12: 16 | I12: 16 | J12: 45 | K12: =H12/4+I12/4+J12/9 -> 13 | L12: 95 | M12: 170 | N12: 195 | O12: =max(M12:N12) -> 195 | P12: 95 | Q12: =L12/20+O12/40+P12/20 -> 14.375 | R12: 7 | S12: 5 | T12: 14 | U12: 8 | V12: 15 | W12: 14 | X12: 20 | Y12: 30 | Z12: 30 | AA12: 30 | AB12: 30 | AC12: =SUM(R12:AB12)/20 -> 10.15 | AD12: 50 | AE12: 340 | AF12: 1 | AG12: =(AC12*AF12) -> 10.15 | AH12: =(AD12+AE12)/40 -> 9.75 | AI12: =G12+K12+Q12+AG12+AH12 -> 84.775
A13: ARYAVEER SINGH RAWAT | B13: B25CS010 | C13: A+ | D13: aryaveersingh@iitbhilai.ac.in | E13: =VLOOKUP(B13, 'CSE-Sandeep'!$B$2:$G$61,5) -> 51 | F13: 40 | G13: =0.5*(E13+F13) -> 45.5 | H13: 19 | I13: 19 | J13: 40 | K13: =H13/4+I13/4+J13/9 -> 13.944444 | L13: 100 | M13: 190 | O13: =max(M13:N13) -> 190 | P13: 85 | Q13: =L13/20+O13/40+P13/20 -> 14 | R13: 7 | S13: 9 | T13: 15 | U13: 11 | V13: 15 | W13: 15 | X13: 20 | Y13: 30 | Z13: 30 | AA13: 30 | AB13: 30 | AC13: =SUM(R13:AB13)/20 -> 10.6 | AD13: 50 | AE13: 335 | AF13: 1 | AG13: =(AC13*AF13) -> 10.6 | AH13: =(AD13+AE13)/40 -> 9.625 | AI13: =G13+K13+Q13+AG13+AH13 -> 93.669444
A14: BHARGAV SHARMA | B14: B25CS011 | C14: A+ | D14: bhargavsharma@iitbhilai.ac.in | E14: =VLOOKUP(B14, 'CSE-Sandeep'!$B$2:$G$61,5) -> 46 | F14: 37 | G14: =0.5*(E14+F14) -> 41.5 | H14: 19 | I14: 19 | J14: 45 | K14: =H14/4+I14/4+J14/9 -> 14.5 | L14: 100 | M14: 200 | O14: =max(M14:N14) -> 200 | P14: 95 | Q14: =L14/20+O14/40+P14/20 -> 14.75 | R14: 7 | S14: 9 | T14: 15 | U14: 11 | V14: 15 | W14: 14 | X14: 20 | Y14: 30 | Z14: 30 | AA14: 30 | AB14: 30 | AC14: =SUM(R14:AB14)/20 -> 10.55 | AD14: 30 | AE14: 340 | AF14: 1 | AG14: =(AC14*AF14) -> 10.55 | AH14: =(AD14+AE14)/40 -> 9.25 | AI14: =G14+K14+Q14+AG14+AH14 -> 90.55
A15: KHANDELWAL BHAVYA SANTKUMAR | B15: B25CS012 | C15: A | D15: bhavyasantku@iitbhilai.ac.in | E15: =VLOOKUP(B15, 'CSE-Sandeep'!$B$2:$G$61,5) -> 50 | F15: 35 | G15: =0.5*(E15+F15) -> 42.5 | H15: 17 | I15: 17 | J15: 34 | K15: =H15/4+I15/4+J15/9 -> 12.277778 | L15: 76 | M15: 190 | O15: =max(M15:N15) -> 190 | P15: 89 | Q15: =L15/20+O15/40+P15/20 -> 13 | R15: 7 | S15: 7 | T15: 14 | U15: 0 | V15: 14 | W15: 14 | X15: 0 | Y15: 30 | Z15: 26 | AA15: 29 | AB15: 28 | AC15: =SUM(R15:AB15)/20 -> 8.45 | AD15: 30 | AE15: 340 | AF15: 1 | AG15: =(AC15*AF15) -> 8.45 | AH15: =(AD15+AE15)/40 -> 9.25 | AI15: =G15+K15+Q15+AG15+AH15 -> 85.477778
A16: NITEESH BODA | B16: B25CS013 | C16: B | D16: bodaniteesh@iitbhilai.ac.in | E16: =VLOOKUP(B16, 'CSE-Sandeep'!$B$2:$G$61,5) -> 38 | F16: 19 | G16: =0.5*(E16+F16) -> 28.5 | H16: 6 | I16: 6 | J16: 35 | K16: =H16/4+I16/4+J16/9 -> 6.8888889 | L16: 90 | M16: 180 | O16: =max(M16:N16) -> 180 | P16: 89 | Q16: =L16/20+O16/40+P16/20 -> 13.45 | R16: 7 | S16: 2 | T16: 15 | U16: 10 | V16: 14 | W16: 14 | X16: 20 | Y16: 30 | Z16: 30 | AA16: 28 | AB16: 28 | AC16: =SUM(R16:AB16)/20 -> 9.9 | AD16: 30 | AE16: 335 | AF16: 1 | AG16: =(AC16*AF16) -> 9.9 | AH16: =(AD16+AE16)/40 -> 9.125 | AI16: =G16+K16+Q16+AG16+AH16 -> 67.863889
A17: DIPA SAHA | B17: B25CS014 | C17: C | D17: dipasaha@iitbhilai.ac.in | E17: =VLOOKUP(B17, 'CSE-Sandeep'!$B$2:$G$61,5) -> 23 | F17: 2 | G17: =0.5*(E17+F17) -> 12.5 | H17: 7 | I17: 7 | J17: 19 | K17: =H17/4+I17/4+J17/9 -> 5.6111111 | L17: 90 | M17: 180 | O17: =max(M17:N17) -> 180 | P17: 95 | Q17: =L17/20+O17/40+P17/20 -> 13.75 | R17: 6 | S17: 7 | T17: 14 | U17: 0 | V17: 14 | W17: 14 | X17: 20 | Y17: 30 | Z17: 30 | AA17: 28 | AB17: 28 | AC17: =SUM(R17:AB17)/20 -> 9.55 | AD17: 50 | AE17: 340 | AF17: 1 | AG17: =(AC17*AF17) -> 9.55 | AH17: =(AD17+AE17)/40 -> 9.75 | AI17: =G17+K17+Q17+AG17+AH17 -> 51.161111
A18: DISHANK VERMA | B18: B25CS015 | C18: C- | D18: dishankverma@iitbhilai.ac.in | E18: =VLOOKUP(B18, 'CSE-Sandeep'!$B$2:$G$61,5) -> 21 | F18: 11 | G18: =0.5*(E18+F18) -> 16 | H18: 6 | I18: 6 | J18: 18 | K18: =H18/4+I18/4+J18/9 -> 5 | L18: 87 | M18: 180 | O18: =max(M18:N18) -> 180 | P18: 85 | Q18: =L18/20+O18/40+P18/20 -> 13.1 | R18: 5 | S18: 4 | T18: 15 | U18: 5 | V18: 5 | W18: 14 | X18: 0 | Y18: 30 | AA18: 28 | AC18: =SUM(R18:AB18)/20 -> 5.3 | AD18: 50 | AE18: 330 | AF18: 1 | AG18: =(AC18*AF18) -> 5.3 | AH18: =(AD18+AE18)/40 -> 9.5 | AI18: =G18+K18+Q18+AG18+AH18 -> 48.9
A19: DIVYANSH KORI | B19: B25CS016 | C19: A+ | D19: divyanshkori@iitbhilai.ac.in | E19: =VLOOKUP(B19, 'CSE-Sandeep'!$B$2:$G$61,5) -> 54 | F19: 36 | G19: =0.5*(E19+F19) -> 45 | H19: 20 | I19: 20 | J19: 36 | K19: =H19/4+I19/4+J19/9 -> 14 | L19: 100 | M19: 180 | O19: =max(M19:N19) -> 180 | P19: 100 | Q19: =L19/20+O19/40+P19/20 -> 14.5 | R19: 7 | S19: 9 | T19: 14 | U19: 8 | V19: 15 | W19: 14 | X19: 20 | Y19: 30 | Z19: 21 | AA19: 30 | AB19: 30 | AC19: =SUM(R19:AB19)/20 -> 9.9 | AD19: 50 | AE19: 340 | AF19: 1 | AG19: =(AC19*AF19) -> 9.9 | AH19: =(AD19+AE19)/40 -> 9.75 | AI19: =G19+K19+Q19+AG19+AH19 -> 93.15
A20: HUSEN FARUKH | B20: B25CS017 | C20: B | D20: farukhhusen@iitbhilai.ac.in | E20: =VLOOKUP(B20, 'CSE-Sandeep'!$B$2:$G$61,5) -> 41 | F20: 28 | G20: =0.5*(E20+F20) -> 34.5 | H20: 8 | I20: 8 | J20: 29 | K20: =H20/4+I20/4+J20/9 -> 7.2222222 | L20: 80 | M20: 180 | O20: =max(M20:N20) -> 180 | P20: 91 | Q20: =L20/20+O20/40+P20/20 -> 13.05 | R20: 6 | S20: 5 | T20: 14 | U20: 8 | V20: 13 | W20: 14 | X20: 19 | Y20: 30 | AA20: 28 | AB20: 28 | AC20: =SUM(R20:AB20)/20 -> 8.25 | AD20: 30 | AE20: 330 | AF20: 1 | AG20: =(AC20*AF20) -> 8.25 | AH20: =(AD20+AE20)/40 -> 9 | AI20: =G20+K20+Q20+AG20+AH20 -> 72.022222
A21: GANDI NAVYA | B21: B25CS018 | C21: B | D21: gandinavya@iitbhilai.ac.in | E21: =VLOOKUP(B21, 'CSE-Sandeep'!$B$2:$G$61,5) -> 43 | F21: 20 | G21: =0.5*(E21+F21) -> 31.5 | H21: 10 | I21: 10 | J21: 20.5 | K21: =H21/4+I21/4+J21/9 -> 7.2777778 | L21: 80 | M21: 180 | O21: =max(M21:N21) -> 180 | P21: 98 | Q21: =L21/20+O21/40+P21/20 -> 13.4 | R21: 7 | S21: 6 | T21: 14 | U21: 8 | V21: 15 | W21: 9 | X21: 20 | Y21: 30 | Z21: 18 | AA21: 28 | AC21: =SUM(R21:AB21)/20 -> 7.75 | AD21: 40 | AE21: 340 | AF21: 1 | AG21: =(AC21*AF21) -> 7.75 | AH21: =(AD21+AE21)/40 -> 9.5 | AI21: =G21+K21+Q21+AG21+AH21 -> 69.427778
A22: GEGGELAPALLY VAISHNAVI | B22: B25CS019 | C22: A | D22: geggelapallyv@iitbhilai.ac.in | E22: =VLOOKUP(B22, 'CSE-Sandeep'!$B$2:$G$61,5) -> 43 | F22: 37 | G22: =0.5*(E22+F22) -> 40 | H22: 12 | I22: 12 | J22: 25 | K22: =H22/4+I22/4+J22/9 -> 8.7777778 | L22: 90 | M22: 190 | O22: =max(M22:N22) -> 190 | P22: 90 | Q22: =L22/20+O22/40+P22/20 -> 13.75 | R22: 7 | S22: 8 | T22: 14 | U22: 12 | V22: 15 | W22: 14 | X22: 20 | Y22: 30 | Z22: 20 | AA22: 30 | AB22: 30 | AC22: =SUM(R22:AB22)/20 -> 10 | AE22: 340 | AF22: 1 | AG22: =(AC22*AF22) -> 10 | AH22: =(AD22+AE22)/40 -> 8.5 | AI22: =G22+K22+Q22+AG22+AH22 -> 81.027778
A23: HARSH | B23: B25CS020 | C23: A- | D23: harshr@iitbhilai.ac.in | E23: =VLOOKUP(B23, 'CSE-Sandeep'!$B$2:$G$61,5) -> 37 | F23: 28 | G23: =0.5*(E23+F23) -> 32.5 | H23: 14 | I23: 14 | J23: 40 | K23: =H23/4+I23/4+J23/9 -> 11.444444 | L23: 95 | M23: 190 | O23: =max(M23:N23) -> 190 | P23: 100 | Q23: =L23/20+O23/40+P23/20 -> 14.5 | R23: 6 | S23: 7 | T23: 15 | U23: 10 | V23: 15 | W23: 14 | X23: 17 | Y23: 30 | Z23: 20 | AA23: 30 | AB23: 30 | AC23: =SUM(R23:AB23)/20 -> 9.7 | AD23: 50 | AE23: 330 | AF23: 1 | AG23: =(AC23*AF23) -> 9.7 | AH23: =(AD23+AE23)/40 -> 9.5 | AI23: =G23+K23+Q23+AG23+AH23 -> 77.644444
A24: HARSH VERMA | B24: B25CS021 | C24: A | D24: harshverma@iitbhilai.ac.in | E24: =VLOOKUP(B24, 'CSE-Sandeep'!$B$2:$G$61,5) -> 45 | F24: 36 | G24: =0.5*(E24+F24) -> 40.5 | H24: 13 | I24: 13 | J24: 30.5 | K24: =H24/4+I24/4+J24/9 -> 9.8888889 | L24: 95 | M24: 190 | O24: =max(M24:N24) -> 190 | P24: 100 | Q24: =L24/20+O24/40+P24/20 -> 14.5 | R24: 7 | S24: 8 | T24: 15 | U24: 12 | V24: 15 | W24: 14 | X24: 18 | Y24: 30 | Z24: 23 | AA24: 30 | AB24: 30 | AC24: =SUM(R24:AB24)/20 -> 10.1 | AD24: 30 | AE24: 335 | AF24: 1 | AG24: =(AC24*AF24) -> 10.1 | AH24: =(AD24+AE24)/40 -> 9.125 | AI24: =G24+K24+Q24+AG24+AH24 -> 84.113889
A25: HARSH VINCE | B25: B25CS022 | C25: A | D25: harshvince@iitbhilai.ac.in | E25: =VLOOKUP(B25, 'CSE-Sandeep'!$B$2:$G$61,5) -> 41 | F25: 30 | G25: =0.5*(E25+F25) -> 35.5 | H25: 7 | I25: 16.5 | J25: 40 | K25: =H25/4+I25/4+J25/9 -> 10.319444 | L25: 100 | M25: 200 | O25: =max(M25:N25) -> 200 | P25: 100 | Q25: =L25/20+O25/40+P25/20 -> 15 | R25: 7 | S25: 7 | T25: 15 | U25: 11 | V25: 15 | W25: 15 | X25: 18 | Y25: 30 | Z25: 30 | AA25: 30 | AB25: 30 | AC25: =SUM(R25:AB25)/20 -> 10.4 | AD25: 50 | AE25: 340 | AF25: 1 | AG25: =(AC25*AF25) -> 10.4 | AH25: =(AD25+AE25)/40 -> 9.75 | AI25: =G25+K25+Q25+AG25+AH25 -> 80.969444
A26: HARSHIT VERMA | B26: B25CS023 | C26: A- | D26: harshitverma@iitbhilai.ac.in | E26: =VLOOKUP(B26, 'CSE-Sandeep'!$B$2:$G$61,5) -> 50 | F26: 30 | G26: =0.5*(E26+F26) -> 40 | H26: 12 | I26: 14.5 | J26: 28 | K26: =H26/4+I26/4+J26/9 -> 9.7361111 | L26: 100 | M26: 170 | N26: 195 | O26: =max(M26:N26) -> 195 | Q26: =L26/20+O26/40+P26/20 -> 9.875 | R26: 7 | S26: 5 | T26: 7.5 | U26: 4 | V26: 10 | W26: 15 | X26: 16 | Y26: 30 | Z26: 30 | AA26: 29 | AB26: 28 | AC26: =SUM(R26:AB26)/20 -> 9.075 | AD26: 50 | AE26: 300 | AF26: 1 | AG26: =(AC26*AF26) -> 9.075 | AH26: =(AD26+AE26)/40 -> 8.75 | AI26: =G26+K26+Q26+AG26+AH26 -> 77.436111
A27: HARSHITA ARIMAKALA | B27: B25CS024 | C27: A | D27: harshitaarima@iitbhilai.ac.in | E27: =VLOOKUP(B27, 'CSE-Sandeep'!$B$2:$G$61,5) -> 47 | F27: 31 | G27: =0.5*(E27+F27) -> 39 | H27: 16.5 | I27: 16 | J27: 33 | K27: =H27/4+I27/4+J27/9 -> 11.791667 | L27: 100 | M27: 153 | O27: =max(M27:N27) -> 153 | P27: 98 | Q27: =L27/20+O27/40+P27/20 -> 13.725 | S27: 5 | T27: 15 | U27: 11 | V27: 11 | W27: 15 | X27: 20 | Y27: 30 | Z27: 30 | AA27: 30 | AB27: 30 | AC27: =SUM(R27:AB27)/20 -> 9.85 | AD27: 50 | AE27: 350 | AF27: 1 | AG27: =(AC27*AF27) -> 9.85 | AH27: =(AD27+AE27)/40 -> 10 | AI27: =G27+K27+Q27+AG27+AH27 -> 84.366667
A28: ISHAN UMESH GHATGE | B28: B25CS025 | C28: A- | D28: ishanumesh@iitbhilai.ac.in | E28: =VLOOKUP(B28, 'CSE-Sandeep'!$B$2:$G$61,5) -> 36 | F28: 29 | G28: =0.5*(E28+F28) -> 32.5 | H28: 16 | I28: 13.5 | J28: 35 | K28: =H28/4+I28/4+J28/9 -> 11.263889 | L28: 100 | M28: 200 | O28: =max(M28:N28) -> 200 | P28: 96 | Q28: =L28/20+O28/40+P28/20 -> 14.8 | R28: 7 | S28: 7 | T28: 10 | U28: 12 | V28: 14 | W28: 15 | X28: 20 | Y28: 30 | Z28: 30 | AA28: 29 | AB28: 30 | AC28: =SUM(R28:AB28)/20 -> 10.2 | AD28: 30 | AE28: 330 | AF28: 1 | AG28: =(AC28*AF28) -> 10.2 | AH28: =(AD28+AE28)/40 -> 9 | AI28: =G28+K28+Q28+AG28+AH28 -> 77.763889
A29: JAMBUKIYA PARTH BHARATBHAI | B29: B25CS026 | C29: A | D29: jambukiyaparth@iitbhilai.ac.in | E29: =VLOOKUP(B29, 'CSE-Sandeep'!$B$2:$G$61,5) -> 47 | F29: 27 | G29: =0.5*(E29+F29) -> 37 | H29: 15 | I29: 15 | J29: 35 | K29: =H29/4+I29/4+J29/9 -> 11.388889 | L29: 100 | M29: 195 | O29: =max(M29:N29) -> 195 | P29: 98 | Q29: =L29/20+O29/40+P29/20 -> 14.775 | R29: 6 | S29: 6 | T29: 11.5 | U29: 8 | V29: 15 | W29: 14 | X29: 20 | Y29: 29 | Z29: 30 | AA29: 30 | AB29: 30 | AC29: =SUM(R29:AB29)/20 -> 9.975 | AD29: 50 | AE29: 330 | AF29: 1 | AG29: =(AC29*AF29) -> 9.975 | AH29: =(AD29+AE29)/40 -> 9.5 | AI29: =G29+K29+Q29+AG29+AH29 -> 82.638889
A30: KAKARLA VIJAYA RAMI REDDY | B30: B25CS027 | C30: FS | D30: kakarlavijaya@iitbhilai.ac.in | E30: =VLOOKUP(B30, 'CSE-Sandeep'!$B$2:$G$61,5) -> 18 | F30: 4 | G30: =0.5*(E30+F30) -> 11 | H30: 3.5 | I30: 8.5 | J30: 30 | K30: =H30/4+I30/4+J30/9 -> 6.3333333 | L30: 85 | M30: 145 | O30: =max(M30:N30) -> 145 | P30: 100 | Q30: =L30/20+O30/40+P30/20 -> 12.875 | R30: 6 | S30: 6 | T30: 7 | U30: 11 | V30: 2 | W30: 8 | X30: 20 | Y30: 30 | Z30: 30 | AA30: 28 | AB30: 28 | AC30: =SUM(R30:AB30)/20 -> 8.8 | AD30: 40 | AE30: 350 | AF30: 1 | AG30: =(AC30*AF30) -> 8.8 | AH30: =(AD30+AE30)/40 -> 9.75 | AI30: =G30+K30+Q30+AG30+AH30 -> 48.758333 | AJ30: C-
A31: krity Loka | B31: B25CS028 | C31: A | D31: kasukurthiloka@iitbhilai.ac.in | E31: =VLOOKUP(B31, 'CSE-Sandeep'!$B$2:$G$61,5) -> 53 | F31: 31 | G31: =0.5*(E31+F31) -> 42 | H31: 16 | I31: 17 | J31: 40 | K31: =H31/4+I31/4+J31/9 -> 12.694444 | L31: 100 | M31: 80 | O31: =max(M31:N31) -> 80 | P31: 90 | Q31: =L31/20+O31/40+P31/20 -> 11.5 | R31: 7 | S31: 4 | T31: 13 | U31: 7 | V31: 14 | W31: 15 | X31: 20 | Y31: 29 | Z31: 0 | AA31: 28 | AB31: 28 | AC31: =SUM(R31:AB31)/20 -> 8.25 | AD31: 50 | AE31: 350 | AF31: 1 | AG31: =(AC31*AF31) -> 8.25 | AH31: =(AD31+AE31)/40 -> 10 | AI31: =G31+K31+Q31+AG31+AH31 -> 84.444444
A32: KOLLI VENKATA KUTUMBA NIHAR | B32: B25CS029 | C32: A | D32: kollivenkata@iitbhilai.ac.in | E32: =VLOOKUP(B32, 'CSE-Sandeep'!$B$2:$G$61,5) -> 47 | F32: 33 | G32: =0.5*(E32+F32) -> 40 | H32: 10.5 | I32: 15 | J32: 40 | K32: =H32/4+I32/4+J32/9 -> 10.819444 | L32: 100 | M32: 200 | O32: =max(M32:N32) -> 200 | P32: 98 | Q32: =L32/20+O32/40+P32/20 -> 14.9 | R32: 7 | S32: 6 | T32: 8 | U32: 3 | V32: 14 | W32: 13 | X32: 18 | Y32: 29 | Z32: 30 | AA32: 29 | AB32: 30 | AC32: =SUM(R32:AB32)/20 -> 9.35 | AD32: 40 | AE32: 350 | AF32: 1 | AG32: =(AC32*AF32) -> 9.35 | AH32: =(AD32+AE32)/40 -> 9.75 | AI32: =G32+K32+Q32+AG32+AH32 -> 84.819444
A33: BASUMATARY MADHURJYA PRASAD | B33: B25CS030 | C33: A | D33: madhurjyapr@iitbhilai.ac.in | E33: =VLOOKUP(B33, 'CSE-Sandeep'!$B$2:$G$61,5) -> 44 | F33: 29 | G33: =0.5*(E33+F33) -> 36.5 | H33: 15 | I33: 11 | J33: 34 | K33: =H33/4+I33/4+J33/9 -> 10.277778 | L33: 100 | M33: 184 | O33: =max(M33:N33) -> 184 | P33: 100 | Q33: =L33/20+O33/40+P33/20 -> 14.6 | R33: 6 | S33: 8 | T33: 14 | U33: 12 | V33: 15 | W33: 15 | X33: 20 | Y33: 30 | Z33: 30 | AA33: 30 | AB33: 29 | AC33: =SUM(R33:AB33)/20 -> 10.45 | AD33: 50 | AE33: 350 | AF33: 1 | AG33: =(AC33*AF33) -> 10.45 | AH33: =(AD33+AE33)/40 -> 10 | AI33: =G33+K33+Q33+AG33+AH33 -> 81.827778
A34: MADUR GANGA MANOJ KUMAR | B34: B25CS031 | C34: A- | D34: madurganga@iitbhilai.ac.in | E34: =VLOOKUP(B34, 'CSE-Sandeep'!$B$2:$G$61,5) -> 35 | F34: 33 | G34: =0.5*(E34+F34) -> 34 | H34: 10 | I34: 11 | J34: 25 | K34: =H34/4+I34/4+J34/9 -> 8.0277778 | L34: 100 | M34: 170 | O34: =max(M34:N34) -> 170 | P34: 97 | Q34: =L34/20+O34/40+P34/20 -> 14.1 | R34: 5 | S34: 5 | T34: 12 | U34: 8 | V34: 9 | W34: 8 | X34: 12 | Y34: 28 | Z34: 30 | AA34: 29 | AC34: =SUM(R34:AB34)/20 -> 7.3 | AD34: 40 | AE34: 330 | AF34: 1 | AG34: =(AC34*AF34) -> 7.3 | AH34: =(AD34+AE34)/40 -> 9.25 | AI34: =G34+K34+Q34+AG34+AH34 -> 72.677778
A35: MITTIREDDI PAVAN KUMAR | B35: B25CS032 | C35: B- | D35: mittireddipavan@iitbhilai.ac.in | E35: =VLOOKUP(B35, 'CSE-Sandeep'!$B$2:$G$61,5) -> 35 | F35: 21 | G35: =0.5*(E35+F35) -> 28 | H35: 11.5 | I35: 4.5 | J35: 17.5 | K35: =H35/4+I35/4+J35/9 -> 5.9444444 | L35: 90 | M35: 96 | O35: =max(M35:N35) -> 96 | P35: 95 | Q35: =L35/20+O35/40+P35/20 -> 11.65 | R35: 4 | S35: 2 | T35: 14 | U35: 8 | V35: 11 | W35: 8 | X35: 8 | Y35: 28 | Z35: 26 | AA35: 30 | AB35: 28 | AC35: =SUM(R35:AB35)/20 -> 8.35 | AD35: 50 | AE35: 330 | AF35: 1 | AG35: =(AC35*AF35) -> 8.35 | AH35: =(AD35+AE35)/40 -> 9.5 | AI35: =G35+K35+Q35+AG35+AH35 -> 63.444444
A36: ABHAY NAMAN AYUSH | B36: B25CS033 | C36: A+ | D36: namanayush@iitbhilai.ac.in | E36: =VLOOKUP(B36, 'CSE-Sandeep'!$B$2:$G$61,5) -> 52 | F36: 38 | G36: =0.5*(E36+F36) -> 45 | H36: 10 | I36: 19 | J36: 30 | K36: =H36/4+I36/4+J36/9 -> 10.583333 | L36: 100 | M36: 200 | O36: =max(M36:N36) -> 200 | P36: 100 | Q36: =L36/20+O36/40+P36/20 -> 15 | R36: 7 | S36: 7 | T36: 15 | U36: 11 | V36: 14 | W36: 15 | X36: 20 | Y36: 29 | Z36: 25 | AA36: 30 | AB36: 30 | AC36: =SUM(R36:AB36)/20 -> 10.15 | AD36: 45 | AE36: 350 | AF36: 1 | AG36: =(AC36*AF36) -> 10.15 | AH36: =(AD36+AE36)/40 -> 9.875 | AI36: =G36+K36+Q36+AG36+AH36 -> 90.608333
A37: NAMAN GUPTA | B37: B25CS034 | C37: A- | D37: namangupta@iitbhilai.ac.in | E37: =VLOOKUP(B37, 'CSE-Sandeep'!$B$2:$G$61,5) -> 44 | F37: 32 | G37: =0.5*(E37+F37) -> 38 | H37: 12 | I37: 12 | J37: 21 | K37: =H37/4+I37/4+J37/9 -> 8.3333333 | L37: 100 | M37: 180 | O37: =max(M37:N37) -> 180 | P37: 94 | Q37: =L37/20+O37/40+P37/20 -> 14.2 | R37: 0 | S37: 6 | T37: 10.5 | U37: 9 | V37: 15 | W37: 15 | X37: 19 | Y37: 26 | Z37: 27 | AA37: 29 | AB37: 27 | AC37: =SUM(R37:AB37)/20 -> 9.175 | AD37: 50 | AE37: 340 | AF37: 1 | AG37: =(AC37*AF37) -> 9.175 | AH37: =(AD37+AE37)/40 -> 9.75 | AI37: =G37+K37+Q37+AG37+AH37 -> 79.458333
A38: GHOSH NAVANIL | B38: B25CS035 | C38: A | D38: navanilghosh@iitbhilai.ac.in | E38: =VLOOKUP(B38, 'CSE-Sandeep'!$B$2:$G$61,5) -> 44 | F38: 36 | G38: =0.5*(E38+F38) -> 40 | H38: 15 | I38: 11 | J38: 36 | K38: =H38/4+I38/4+J38/9 -> 10.5 | L38: 100 | M38: 187 | O38: =max(M38:N38) -> 187 | P38: 89 | Q38: =L38/20+O38/40+P38/20 -> 14.125 | R38: 7 | S38: 10 | T38: 14 | U38: 8 | V38: 12 | W38: 15 | X38: 17 | Y38: 28 | Z38: 26 | AA38: 29 | AB38: 30 | AC38: =SUM(R38:AB38)/20 -> 9.8 | AD38: 50 | AE38: 350 | AF38: 1 | AG38: =(AC38*AF38) -> 9.8 | AH38: =(AD38+AE38)/40 -> 10 | AI38: =G38+K38+Q38+AG38+AH38 -> 84.425
A39: NISHCHAL JAIN | B39: B25CS036 | C39: A | D39: nishchaljain@iitbhilai.ac.in | E39: =VLOOKUP(B39, 'CSE-Sandeep'!$B$2:$G$61,5) -> 50 | F39: 29 | G39: =0.5*(E39+F39) -> 39.5 | H39: 15 | I39: 10 | J39: 36 | K39: =H39/4+I39/4+J39/9 -> 10.25 | L39: 85 | M39: 195 | O39: =max(M39:N39) -> 195 | P39: 100 | Q39: =L39/20+O39/40+P39/20 -> 14.125 | R39: 7 | S39: 9 | T39: 12 | U39: 11 | V39: 15 | W39: 15 | X39: 20 | Y39: 30 | Z39: 28 | AA39: 30 | AB39: 30 | AC39: =SUM(R39:AB39)/20 -> 10.35 | AD39: 30 | AE39: 330 | AF39: 1 | AG39: =(AC39*AF39) -> 10.35 | AH39: =(AD39+AE39)/40 -> 9 | AI39: =G39+K39+Q39+AG39+AH39 -> 83.225
A40: TEJA PALAVALASA PAWAN | B40: B25CS037 | C40: A | D40: palavalasapaw@iitbhilai.ac.in | E40: =VLOOKUP(B40, 'CSE-Sandeep'!$B$2:$G$61,5) -> 53 | F40: 32 | G40: =0.5*(E40+F40) -> 42.5 | H40: 14 | I40: 20 | J40: 43 | K40: =H40/4+I40/4+J40/9 -> 13.277778 | L40: 100 | M40: 195 | O40: =max(M40:N40) -> 195 | P40: 90 | Q40: =L40/20+O40/40+P40/20 -> 14.375 | R40: 7 | S40: 7 | T40: 13 | U40: 10 | V40: 14 | W40: 11 | X40: 20 | Y40: 25 | Z40: 27 | AA40: 29 | AB40: 28 | AC40: =SUM(R40:AB40)/20 -> 9.55 | AD40: 0 | AE40: 330 | AF40: 1 | AG40: =(AC40*AF40) -> 9.55 | AH40: =(AD40+AE40)/40 -> 8.25 | AI40: =G40+K40+Q40+AG40+AH40 -> 87.952778
...

Sheet Sheet3
A1: ID | B1: Grade
A2: B24DS035 | B2: A-
A3: B24EC013 | B3: A
A4: B24EC016 | B4: A
A5: B24MT001 | B5: A-
A6: B25CS002 | B6: A
A7: B25CS003 | B7: A-
A8: B25CS004 | B8: A
A9: B25CS005 | B9: B
A10: B25CS006 | B10: A
A11: B25CS007 | B11: B-
A12: B25CS008 | B12: A
... A331: S25MA018 | B331: A-

Sheet Copy of LetterGrades-CSL100-Int
A1: Name | B1: ID | C1: SIS Login ID | D1: End Sem (60552481) | E1: Mid Sem (58777481) | F1: ExamFinal | G1: Offline Quiz 1 (58279106) | H1: Offline Quiz 2 (59288522) | I1: Offline Quiz 3 (60480072) | J1: QuizFinal | K1: Asg1 | L1: Sliding Characters Game Development in Python (57463646) | M1: Python Clock Assignment (Optional*) (58717731) | N1: Asg 2 | O1: Analyzing call record/history data (59288548) | P1: Asg_Final | Q1: Practice Quiz (57192616) | R1: Practice Quiz - 2 (57710859) | S1: Practice Quiz - 3 (57710877) | T1: Practice Quiz - 4 (57710885) | U1: Practice Sheet 1.1 (57352610) | V1: Practice Sheet 1 (soft copy) (57328669) | W1: Practice Sheet 1.2 + Chapter 2 of IITD Notes (57466219) | X1: Selected Problems from Practice Sheets 2, 3, 4 (57884237) | Y1: Practice Sheet 5 and 6 questions (58107442) | Z1: Practice Sheet - Python (59580084) | AA1: Practice Sheet - Whole Syllabus (60148873) | AB1: PracticeSheetTotal | AC1: Course Project Proposal (59288714) | AD1: Final Project (60057608) | AE1: LabAttendance | AF1: ProjectFinal | AG1: CourseTotal
A2: KUMAR GUMMALA VENKATA DHANUSH | B2: B25EC016 | C2: gvdkumar@iitbhilai.ac.in | D2: =VLOOKUP(B2,'EC-Nitin'!$B$2:$F$46,5) -> 0 | F2: =0.5*(D2+E2) -> 0 | I2: -1 | J2: =G2/4+H2/4+I2/9 -> -0.11111111 | N2: =max(L2:M2) -> 0 | P2: =K2/20+N2/40+O2/20 -> 0 | V2: 14 | Z2: 30 | AB2: =SUM(Q2:AA2)/20 -> 2.2 | AF2: =(AC2+AD2)/40 -> 0 | AG2: =F2+J2+P2+AB2+AF2 -> 2.0888889 | AH2: F
A3: DUGAR SWARNA KANTI | B3: B25CS057 | C3: swarnakanti@iitbhilai.ac.in | D3: =VLOOKUP(B3, 'CSE-Sandeep'!$B$2:$G$61,5) -> 0 | F3: =0.5*(D3+E3) -> 0 | I3: -1 | J3: =G3/4+H3/4+I3/9 -> -0.11111111 | K3: 100 | N3: =max(L3:M3) -> 0 | P3: =K3/20+N3/40+O3/20 -> 5 | Q3: 7 | R3: 10 | U3: 15 | V3: 15 | W3: 20 | AB3: =SUM(Q3:AA3)/20 -> 3.35 | AF3: =(AC3+AD3)/40 -> 0 | AG3: =F3+J3+P3+AB3+AF3 -> 8.2388889 | AH3: F
A4: Pal Ankit | B4: B25EE008 | C4: ankitpal@iitbhilai.ac.in | D4: =VLOOKUP(B4, 'EE-Nitin'!$B$2:$F$57,5) -> 0 | F4: =0.5*(D4+E4) -> 0 | G4: 0 | H4: 0 | I4: -1 | J4: =G4/4+H4/4+I4/9 -> -0.11111111 | K4: 93 | L4: 0 | N4: =max(L4:M4) -> 0 | P4: =K4/20+N4/40+O4/20 -> 4.65 | Q4: 7 | R4: 9 | S4: 10 | T4: 11 | U4: 14.5 | V4: 14.5 | W4: 20 | X4: 0 | Y4: 0 | AB4: =SUM(Q4:AA4)/20 -> 4.3 | AF4: =(AC4+AD4)/40 -> 0 | AG4: =F4+J4+P4+AB4+AF4 -> 8.8388889 | AH4: F
A5: POTHUMUDI PRADEEP KUMAR | B5: B25EE040 | C5: pothumudipr@iitbhilai.ac.in | D5: =VLOOKUP(B5, 'EE-Nitin'!$B$2:$F$57,5) -> 12 | E5: 4 | F5: =0.5*(D5+E5) -> 8 | G5: 1.5 | H5: 3 | I5: 0 | J5: =G5/4+H5/4+I5/9 -> 1.125 | K5: 0 | L5: 95 | N5: =max(L5:M5) -> 95 | O5: 80 | P5: =K5/20+N5/40+O5/20 -> 6.375 | Q5: 6 | R5: 5 | S5: 0 | T5: 8 | U5: 5 | V5: 13 | W5: 18 | X5: 28 | Y5: 0 | AA5: 29 | AB5: =SUM(Q5:AA5)/20 -> 5.6 | AC5: 50 | AD5: 280 | AF5: =(AC5+AD5)/40 -> 8.25 | AG5: =F5+J5+P5+AB5+AF5 -> 29.35 | AH5: FS
A6: C ASHWIN NAINAAR R | B6: B25MM005 | C6: anainaarrc@iitbhilai.ac.in | D6: =VLOOKUP(B6,'MM-Subhashree'!$B$2:F$26,5) -> 20 | E6: 11 | F6: =0.5*(D6+E6) -> 15.5 | H6: 5 | I6: 16 | J6: =G6/4+H6/4+I6/9 -> 3.0277778 | M6: 165 | N6: =max(L6:M6) -> 165 | P6: =K6/20+N6/40+O6/20 -> 4.125 | Q6: 6 | R6: 5 | S6: 6 | V6: 10 | W6: 18 | Z6: 28 | AB6: =SUM(Q6:AA6)/20 -> 3.65 | AD6: 340 | AF6: =(AC6+AD6)/40 -> 8.5 | AG6: =F6+J6+P6+AB6+AF6 -> 34.802778 | AH6: D
A7: ABHINAV SURYA TEJ | B7: B25ME023 | C7: dasuryatej@iitbhilai.ac.in | D7: =VLOOKUP(B7, 'ME-Subhashree'!$B$2:$F$56,5) -> 5 | E7: 7 | F7: =0.5*(D7+E7) -> 6 | G7: 5 | H7: 0 | I7: 40 | J7: =G7/4+H7/4+I7/9 -> 5.6944444 | K7: 100 | L7: 125 | N7: =max(L7:M7) -> 125 | O7: 0 | P7: =K7/20+N7/40+O7/20 -> 8.125 | Q7: 7 | R7: 7 | S7: 15 | T7: 15 | U7: 15 | V7: 13 | W7: 20 | X7: 0 | Y7: 0 | Z7: 29 | AA7: 27 | AB7: =SUM(Q7:AA7)/20 -> 7.4 | AC7: 50 | AD7: 320 | AF7: =(AC7+AD7)/40 -> 9.25 | AG7: =F7+J7+P7+AB7+AF7 -> 36.469444 | AH7: FS
A8: SRIVASTAV SHAURYA | B8: B25ME055 | C8: shauryasv@iitbhilai.ac.in | D8: =VLOOKUP(B8, 'ME-Subhashree'!$B$2:$F$56,5) -> 34 | E8: 22 | F8: =0.5*(D8+E8) -> 28 | I8: -1 | J8: =G8/4+H8/4+I8/9 -> -0.11111111 | L8: 175 | N8: =max(L8:M8) -> 175 | P8: =K8/20+N8/40+O8/20 -> 4.375 | Q8: 7 | R8: 9 | S8: 0 | T8: 12 | V8: 13.5 | W8: 17 | X8: 27.14 | AB8: =SUM(Q8:AA8)/20 -> 4.282 | AF8: =(AC8+AD8)/40 -> 0 | AG8: =F8+J8+P8+AB8+AF8 -> 36.545889 | AH8: D
A9: DASARI YASHWANTH KUMAR | B9: B25DS007 | C9: dasariyashwan@iitbhilai.ac.in | D9: =VLOOKUP(B9,'DSAI-Vikrant'!$B$2:$F$44,5) -> 4 | E9: 6 | F9: =0.5*(D9+E9) -> 5 | G9: 4 | H9: 7.5 | I9: 4 | J9: =G9/4+H9/4+I9/9 -> 3.3194444 | K9: 93 | L9: 121 | N9: =max(L9:M9) -> 121 | O9: 98 | P9: =K9/20+N9/40+O9/20 -> 12.575 | Q9: 6 | R9: 5 | S9: 6 | T9: 0 | U9: 14 | V9: 14 | W9: 18 | X9: 30 | Y9: 30 | Z9: 27 | AA9: 28 | AB9: =SUM(Q9:AA9)/20 -> 8.9 | AC9: 0 | AD9: 300 | AF9: =(AC9+AD9)/40 -> 7.5 | AG9: =F9+J9+P9+AB9+AF9 -> 37.294444 | AH9: FS
A10: VIGNESH S | B10: B25DS033 | C10: svignesh@iitbhilai.ac.in | D10: =VLOOKUP(B10,'DSAI-Vikrant'!$B$2:$F$44,5) -> 15 | E10: 18 | F10: =0.5*(D10+E10) -> 16.5 | G10: 7 | H10: 0 | I10: 5.5 | J10: =G10/4+H10/4+I10/9 -> 2.3611111 | K10: 30 | L10: 165 | N10: =max(L10:M10) -> 165 | O10: 0 | P10: =K10/20+N10/40+O10/20 -> 5.625 | R10: 4 | S10: 8 | T10: 4 | U10: 15 | V10: 15 | W10: 15 | X10: 0 | Y10: 0 | Z10: 30 | AA10: 26 | AB10: =SUM(Q10:AA10)/20 -> 5.85 | AC10: 10 | AD10: 310 | AF10: =(AC10+AD10)/40 -> 8 | AG10: =F10+J10+P10+AB10+AF10 -> 38.336111 | AH10: D
A11: KOTANNAGARI BHARGAV SHASHANK | B11: B25ME038 | C11: kgbshashan@iitbhilai.ac.in | D11: =VLOOKUP(B11, 'ME-Subhashree'!$B$2:$F$56,5) -> 6 | E11: 6 | F11: =0.5*(D11+E11) -> 6 | G11: 3 | H11: 1 | I11: 40 | J11: =G11/4+H11/4+I11/9 -> 5.4444444 | K11: 100 | L11: 100 | N11: =max(L11:M11) -> 100 | O11: 100 | P11: =K11/20+N11/40+O11/20 -> 12.5 | Q11: 6 | R11: 4 | S11: 10 | T11: 10 | U11: 15 | V11: 15 | W11: 20 | X11: 30 | Y11: 30 | AA11: 28 | AB11: =SUM(Q11:AA11)/20 -> 8.4 | AC11: 40 | AD11: 330 | AF11: =(AC11+AD11)/40 -> 9.25 | AG11: =F11+J11+P11+AB11+AF11 -> 41.594444 | AH11: FS
A12: ROHIT SONI | B12: B25ME052 | C12: 105727867094098693539 | D12: =VLOOKUP(B12, 'ME-Subhashree'!$B$2:$F$56,5) -> 19 | E12: 13 | F12: =0.5*(D12+E12) -> 16 | G12: 6.5 | I12: 4 | J12: =G12/4+H12/4+I12/9 -> 2.0694444 | K12: 85 | L12: 180 | N12: =max(L12:M12) -> 180 | P12: =K12/20+N12/40+O12/20 -> 8.75 | Q12: 3 | R12: 5 | S12: 13 | T12: 0 | W12: 7 | X12: 25.62 | Z12: 27 | AA12: 27 | AB12: =SUM(Q12:AA12)/20 -> 5.381 | AC12: 49 | AD12: 340 | AF12: =(AC12+AD12)/40 -> 9.725 | AG12: =F12+J12+P12+AB12+AF12 -> 41.925444 | AH12: D
A13: NITISH KUMAR | B13: S25MA011 | C13: NITISHKUMAR@iitbhilai.ac.in | D13: =VLOOKUP(B13, 'MSC-Vikrant'!B7:F18,5) -> 11 | E13: 11 | F13: =0.5*(D13+E13) -> 11 | G13: 11 | H13: 4 | I13: 3.5 | J13: =G13/4+H13/4+I13/9 -> 4.1388889 | K13: 70 | L13: 162 | M13: 165 | N13: =max(L13:M13) -> 165 | O13: 92 | P13: =K13/20+N13/40+O13/20 -> 12.225 | Q13: 5 | S13: 4 | T13: 5 | U13: 15 | V13: 12 | W13: 15 | X13: 28 | Y13: 18 | Z13: 29 | AB13: =SUM(Q13:AA13)/20 -> 6.55 | AC13: 50 | AD13: 280 | AF13: =(AC13+AD13)/40 -> 8.25 | AG13: =F13+J13+P13+AB13+AF13 -> 42.163889 | AH13: FS
A14: Mangalaram Susheel reddy | B14: B25ME042 | C14: msreddy@iitbhilai.ac.in | D14: =VLOOKUP(B14, 'ME-Subhashree'!$B$2:$F$56,5) -> 27 | E14: 29 | F14: =0.5*(D14+E14) -> 28 | G14: 5 | H14: 6 | I14: 14 | J14: =G14/4+H14/4+I14/9 -> 4.3055556 | K14: 70 | L14: 179 | N14: =max(L14:M14) -> 179 | P14: =K14/20+N14/40+O14/20 -> 7.975 | Q14: 7 | R14: 7 | S14: 10 | T14: 10 | V14: 13 | W14: 17 | AB14: =SUM(Q14:AA14)/20 -> 3.2 | AF14: =(AC14+AD14)/40 -> 0 | AG14: =F14+J14+P14+AB14+AF14 -> 43.480556 | AH14: D
A15: SOUMIL SAHU | B15: B25EE055 | C15: 112247789942064116506 | E15: 28 | F15: =0.5*(D15+E15) -> 14 | G15: 15 | H15: 9 | I15: 0 | J15: =G15/4+H15/4+I15/9 -> 6 | K15: 90 | L15: 185 | N15: =max(L15:M15) -> 185 | O15: 100 | P15: =K15/20+N15/40+O15/20 -> 14.125 | Q15: 7 | R15: 10 | S15: 12 | T15: 12 | U15: 14 | V15: 14 | W15: 20 | X15: 29 | Y15: 28 | Z15: 29 | AB15: =SUM(Q15:AA15)/20 -> 8.75 | AC15: 30 | AD15: 0 | AF15: =(AC15+AD15)/40 -> 0.75 | AG15: =F15+J15+P15+AB15+AF15 -> 43.625 | AH15: A
A16: SIDDHANT VIJAY PUNEKAR | B16: B25DS037 | C16: siddhantvijay@iitbhilai.ac.in | D16: =VLOOKUP(B16,'DSAI-Vikrant'!$B$2:$F$44,5) -> 30 | E16: 3 | F16: =0.5*(D16+E16) -> 16.5 | H16: 11 | I16: 10 | J16: =G16/4+H16/4+I16/9 -> 3.8611111 | K16: 100 | L16: 100 | N16: =max(L16:M16) -> 100 | O16: 80 | P16: =K16/20+N16/40+O16/20 -> 11.5 | Q16: 7 | R16: 4 | S16: 8 | T16: 7 | U16: 15 | V16: 15 | W16: 19 | X16: 0 | Y16: 0 | Z16: 30 | AA16: 28 | AB16: =SUM(Q16:AA16)/20 -> 6.65 | AC16: 30 | AD16: 335 | AF16: =(AC16+AD16)/40 -> 9.125 | AG16: =F16+J16+P16+AB16+AF16 -> 47.636111 | AH16: C-
A17: KumarShubham | B17: S25MA014 | C17: SHUBHAMKUM@iitbhilai.ac.in | D17: =VLOOKUP(B17, 'MSC-Vikrant'!B9:F20,5) -> 21 | E17: 13 | F17: =0.5*(D17+E17) -> 17 | G17: 9 | H17: 1 | I17: 6.5 | J17: =G17/4+H17/4+I17/9 -> 3.2222222 | K17: 80 | L17: 154 | N17: =max(L17:M17) -> 154 | O17: 91 | P17: =K17/20+N17/40+O17/20 -> 12.4 | R17: 7 | T17: 0 | U17: 15 | V17: 10 | W17: 12 | X17: 29 | Y17: 27 | Z17: 28 | AB17: =SUM(Q17:AA17)/20 -> 6.4 | AC17: 50 | AD17: 300 | AF17: =(AC17+AD17)/40 -> 8.75 | AG17: =F17+J17+P17+AB17+AF17 -> 47.772222 | AH17: C-
A18: CHANDU BOLLEDDU | B18: B25EC010 | C18: bchandu@iitbhilai.ac.in | D18: =VLOOKUP(B18,'EC-Nitin'!$B$2:$F$46,5) -> 13 | E18: 10 | F18: =0.5*(D18+E18) -> 11.5 | G18: 9 | H18: 10 | I18: 17 | J18: =G18/4+H18/4+I18/9 -> 6.6388889 | K18: 80 | L18: 100 | N18: =max(L18:M18) -> 100 | O18: 90 | P18: =K18/20+N18/40+O18/20 -> 11 | R18: 7 | S18: 13 | T18: 11 | U18: 14 | V18: 14 | W18: 20 | X18: 30 | Y18: 30 | Z18: 29 | AA18: 28 | AB18: =SUM(Q18:AA18)/20 -> 9.8 | AC18: 50 | AD18: 330 | AF18: =(AC18+AD18)/40 -> 9.5 | AG18: =F18+J18+P18+AB18+AF18 -> 48.438889 | AH18: FS
A19: LAVANYA RATHOD | B19: B25CS043 | C19: rathodlavanya@iitbhilai.ac.in | D19: =VLOOKUP(B19, 'CSE-Sandeep'!$B$2:$G$61,5) -> 15 | E19: 6 | F19: =0.5*(D19+E19) -> 10.5 | G19: 5 | H19: 15 | I19: 20 | J19: =G19/4+H19/4+I19/9 -> 7.2222222 | K19: 100 | L19: 180 | N19: =max(L19:M19) -> 180 | O19: 92 | P19: =K19/20+N19/40+O19/20 -> 14.1 | R19: 0 | T19: 11 | U19: 12 | V19: 15 | W19: 18 | X19: 26 | Y19: 25 | Z19: 28 | AA19: 28 | AB19: =SUM(Q19:AA19)/20 -> 8.15 | AC19: 40 | AD19: 310 | AF19: =(AC19+AD19)/40 -> 8.75 | AG19: =F19+J19+P19+AB19+AF19 -> 48.722222 | AH19: FS
A20: KAKARLA VIJAYA RAMI REDDY | B20: B25CS027 | C20: kakarlavijaya@iitbhilai.ac.in | D20: =VLOOKUP(B20, 'CSE-Sandeep'!$B$2:$G$61,5) -> 18 | E20: 4 | F20: =0.5*(D20+E20) -> 11 | G20: 3.5 | H20: 8.5 | I20: 30 | J20: =G20/4+H20/4+I20/9 -> 6.3333333 | K20: 85 | L20: 145 | N20: =max(L20:M20) -> 145 | O20: 100 | P20: =K20/20+N20/40+O20/20 -> 12.875 | Q20: 6 | R20: 6 | S20: 7 | T20: 11 | U20: 2 | V20: 8 | W20: 20 | X20: 30 | Y20: 30 | Z20: 28 | AA20: 28 | AB20: =SUM(Q20:AA20)/20 -> 8.8 | AC20: 40 | AD20: 350 | AF20: =(AC20+AD20)/40 -> 9.75 | AG20: =F20+J20+P20+AB20+AF20 -> 48.758333 | AH20: FS
A21: Mansu Khute | B21: B25DS022 | C21: 110717464809716125269 | D21: =VLOOKUP(B21,'DSAI-Vikrant'!$B$2:$F$44,5) -> 20 | E21: 11 | F21: =0.5*(D21+E21) -> 15.5 | G21: 6 | H21: 5 | I21: 0 | J21: =G21/4+H21/4+I21/9 -> 2.75 | K21: 90 | L21: 160 | N21: =max(L21:M21) -> 160 | O21: 94 | P21: =K21/20+N21/40+O21/20 -> 13.2 | Q21: 7 | R21: 6 | S21: 7 | T21: 7 | U21: 13 | V21: 12 | W21: 17 | X21: 22 | Y21: 26 | Z21: 28 | AA21: 28 | AB21: =SUM(Q21:AA21)/20 -> 8.65 | AC21: 50 | AD21: 300 | AF21: =(AC21+AD21)/40 -> 8.75 | AG21: =F21+J21+P21+AB21+AF21 -> 48.85 | AH21: C-
A22: DISHANK VERMA | B22: B25CS015 | C22: dishankverma@iitbhilai.ac.in | D22: =VLOOKUP(B22, 'CSE-Sandeep'!$B$2:$G$61,5) -> 21 | E22: 11 | F22: =0.5*(D22+E22) -> 16 | G22: 6 | H22: 6 | I22: 18 | J22: =G22/4+H22/4+I22/9 -> 5 | K22: 87 | L22: 180 | N22: =max(L22:M22) -> 180 | O22: 85 | P22: =K22/20+N22/40+O22/20 -> 13.1 | Q22: 5 | R22: 4 | S22: 15 | T22: 5 | U22: 5 | V22: 14 | W22: 0 | X22: 30 | Z22: 28 | AB22: =SUM(Q22:AA22)/20 -> 5.3 | AC22: 50 | AD22: 330 | AF22: =(AC22+AD22)/40 -> 9.5 | AG22: =F22+J22+P22+AB22+AF22 -> 48.9 | AH22: C-
A23: RAMAVATH SAI CHARAN | B23: B25MT021 | C23: rscharan@iitbhilai.ac.in | D23: =VLOOKUP(B23,MT!$B$2:$F$30,5) -> 28 | F23: =0.5*(D23+E23) -> 14 | G23: 0 | H23: 6.5 | I23: 17 | J23: =G23/4+H23/4+I23/9 -> 3.5138889 | K23: 90 | L23: 192 | N23: =max(L23:M23) -> 192 | O23: 100 | P23: =K23/20+N23/40+O23/20 -> 14.3 | Q23: 6 | R23: 6 | S23: 6 | U23: 15 | V23: 15 | W23: 20 | X23: 27 | Y23: 28 | Z23: 28 | AA23: 29 | AB23: =SUM(Q23:AA23)/20 -> 9 | AC23: 28 | AD23: 325 | AF23: =(AC23+AD23)/40 -> 8.825 | AG23: =F23+J23+P23+AB23+AF23 -> 49.638889 | AH23: C-
A24: JORWAL ARYAN | B24: B25EE012 | C24: aryanjorwal@iitbhilai.ac.in | D24: =VLOOKUP(B24, 'EE-Nitin'!$B$2:$F$57,5) -> 26 | E24: 20 | F24: =0.5*(D24+E24) -> 23 | G24: 7 | H24: 0 | I24: 21 | J24: =G24/4+H24/4+I24/9 -> 4.0833333 | K24: 84 | L24: 0 | N24: =max(L24:M24) -> 0 | O24: 97 | P24: =K24/20+N24/40+O24/20 -> 9.05 | Q24: 7 | R24: 9 | S24: 7 | T24: 10 | U24: 13 | V24: 12 | W24: 18 | X24: 0 | Y24: 0 | Z24: 29 | AB24: =SUM(Q24:AA24)/20 -> 5.25 | AC24: 0 | AD24: 343 | AF24: =(AC24+AD24)/40 -> 8.575 | AG24: =F24+J24+P24+AB24+AF24 -> 49.958333 | AH24: C-
A25: CHANDRA DHANAVATH SHIVA | B25: B25EC011 | C25: dschandra@iitbhilai.ac.in | D25: =VLOOKUP(B25,'EC-Nitin'!$B$2:$F$46,5) -> 20 | E25: 7 | F25: =0.5*(D25+E25) -> 13.5 | G25: 10 | H25: 15 | I25: 22 | J25: =G25/4+H25/4+I25/9 -> 8.6944444 | K25: 90 | L25: 180 | N25: =max(L25:M25) -> 180 | P25: =K25/20+N25/40+O25/20 -> 9 | Q25: 6 | R25: 5 | S25: 14 | T25: 13 | U25: 14 | V25: 13 | W25: 18 | X25: 30 | Y25: 30 | Z25: 28 | AA25: 28 | AB25: =SUM(Q25:AA25)/20 -> 9.95 | AC25: 30 | AD25: 330 | AF25: =(AC25+AD25)/40 -> 9 | AG25: =F25+J25+P25+AB25+AF25 -> 50.144444 | AH25: C-
A26: KUMAR ABHISHEK | B26: B25EE002 | C26: abhishekkumar@iitbhilai.ac.in | D26: =VLOOKUP(B26, 'EE-Nitin'!$B$2:$F$57,5) -> 26 | F26: =0.5*(D26+E26) -> 13 | G26: 4 | H26: 7 | I26: 20 | J26: =G26/4+H26/4+I26/9 -> 4.9722222 | K26: 95 | L26: 170 | N26: =max(L26:M26) -> 170 | O26: 96 | P26: =K26/20+N26/40+O26/20 -> 13.8 | Q26: 7 | R26: 3 | S26: 0 | T26: 12 | U26: 14.5 | V26: 14 | W26: 19.5 | X26: 28 | Y26: 28 | Z26: 29 | AA26: 29 | AB26: =SUM(Q26:AA26)/20 -> 9.2 | AC26: 45 | AD26: 345 | AF26: =(AC26+AD26)/40 -> 9.75 | AG26: =F26+J26+P26+AB26+AF26 -> 50.722222 | AH26: C
A27: Bablu Bunker | B27: B25ME016 | C27: 101063313082382402792 | D27: =VLOOKUP(B27, 'ME-Subhashree'!$B$2:$F$56,5) -> 27 | E27: 14 | F27: =0.5*(D27+E27) -> 20.5 | G27: 2 | H27: 6 | I27: 27 | J27: =G27/4+H27/4+I27/9 -> 5 | K27: 80 | L27: 140 | N27: =max(L27:M27) -> 140 | O27: 80 | P27: =K27/20+N27/40+O27/20 -> 11.5 | Q27: 0 | R27: 10 | S27: 9 | T27: 5 | U27: 15 | V27: 13 | W27: 16 | X27: 29 | Y27: 0 | Z27: 30 | AA27: 27 | AB27: =SUM(Q27:AA27)/20 -> 7.7 | AC27: 0 | AD27: 250 | AF27: =(AC27+AD27)/40 -> 6.25 | AG27: =F27+J27+P27+AB27+AF27 -> 50.95 | AH27: C
A28: Aditya Gupta | B28: S25MA001 | C28: ADITYAGUPTA@iitbhilai.ac.in | D28: =VLOOKUP(B28, 'MSC-Vikrant'!B2:F13,5) -> 20 | E28: 11 | F28: =0.5*(D28+E28) -> 15.5 | G28: 9 | H28: 10 | I28: 22 | J28: =G28/4+H28/4+I28/9 -> 7.1944444 | K28: 50 | L28: 165 | M28: 160 | N28: =max(L28:M28) -> 165 | O28: 92 | P28: =K28/20+N28/40+O28/20 -> 11.225 | Q28: 6 | S28: 10 | T28: 5 | U28: 10 | V28: 12 | W28: 15 | X28: 28 | Y28: 30 | Z28: 28 | AA28: 29 | AB28: =SUM(Q28:AA28)/20 -> 8.65 | AC28: 50 | AD28: 290 | AF28: =(AC28+AD28)/40 -> 8.5 | AG28: =F28+J28+P28+AB28+AF28 -> 51.069444 | AH28: C
A29: DIPA SAHA | B29: B25CS014 | C29: dipasaha@iitbhilai.ac.in | D29: =VLOOKUP(B29, 'CSE-Sandeep'!$B$2:$G$61,5) -> 23 | E29: 2 | F29: =0.5*(D29+E29) -> 12.5 | G29: 7 | H29: 7 | I29: 19 | J29: =G29/4+H29/4+I29/9 -> 5.6111111 | K29: 90 | L29: 180 | N29: =max(L29:M29) -> 180 | O29: 95 | P29: =K29/20+N29/40+O29/20 -> 13.75 | Q29: 6 | R29: 7 | S29: 14 | T29: 0 | U29: 14 | V29: 14 | W29: 20 | X29: 30 | Y29: 30 | Z29: 28 | AA29: 28 | AB29: =SUM(Q29:AA29)/20 -> 9.55 | AC29: 50 | AD29: 340 | AF29: =(AC29+AD29)/40 -> 9.75 | AG29: =F29+J29+P29+AB29+AF29 -> 51.161111 | AH29: C
A30: VIVEK WALIKAR | B30: B25EE059 | C30: vivekwalikar@iitbhilai.ac.in | D30: =VLOOKUP(B30, 'EE-Nitin'!$B$2:$F$57,5) -> 29 | E30: 21 | F30: =0.5*(D30+E30) -> 25 | G30: 4.5 | H30: 0 | I30: 17 | J30: =G30/4+H30/4+I30/9 -> 3.0138889 | K30: 100 | M30: 0 | N30: =max(L30:M30) -> 0 | O30: 90 | P30: =K30/20+N30/40+O30/20 -> 9.5 | Q30: 7 | R30: 9 | S30: 0 | T30: 0 | U30: 15 | V30: 15 | W30: 20 | X30: 0 | Y30: 0 | Z30: 30 | AA30: 27 | AB30: =SUM(Q30:AA30)/20 -> 6.15 | AC30: 0 | AD30: 310 | AF30: =(AC30+AD30)/40 -> 7.75 | AG30: =F30+J30+P30+AB30+AF30 -> 51.413889 | AH30: C
A31: BHUKYA PAVAN | B31: B25EE014 | C31: bhukyapavan@iitbhilai.ac.in | D31: =VLOOKUP(B31, 'EE-Nitin'!$B$2:$F$57,5) -> 15 | E31: 19 | F31: =0.5*(D31+E31) -> 17 | G31: 2 | H31: 0 | I31: 16 | J31: =G31/4+H31/4+I31/9 -> 2.2777778 | K31: 93 | L31: 180 | N31: =max(L31:M31) -> 180 | O31: 96 | P31: =K31/20+N31/40+O31/20 -> 13.95 | Q31: 6 | R31: 4 | S31: 0 | T31: 9 | U31: 13 | V31: 10 | W31: 18 | X31: 26 | Y31: 29 | Z31: 28 | AA31: 28 | AB31: =SUM(Q31:AA31)/20 -> 8.55 | AC31: 45 | AD31: 341 | AF31: =(AC31+AD31)/40 -> 9.65 | AG31: =F31+J31+P31+AB31+AF31 -> 51.427778 | AH31: C
A32: DISABEN SHAILESHBHAI | B32: S25MA004 | C32: DISABENSP@iitbhilai.ac.in | D32: =VLOOKUP(B32, 'MSC-Vikrant'!B4:F15,5) -> 28 | E32: 5 | F32: =0.5*(D32+E32) -> 16.5 | G32: 9 | H32: 10 | I32: 12 | J32: =G32/4+H32/4+I32/9 -> 6.0833333 | K32: 80 | L32: 158 | N32: =max(L32:M32) -> 158 | O32: 93 | P32: =K32/20+N32/40+O32/20 -> 12.6 | Q32: 7 | R32: 7 | S32: 8 | T32: 0 | U32: 14 | V32: 15 | W32: 12 | X32: 29 | Y32: 27 | Z32: 28 | AB32: =SUM(Q32:AA32)/20 -> 7.35 | AC32: 50 | AD32: 310 | AF32: =(AC32+AD32)/40 -> 9 | AG32: =F32+J32+P32+AB32+AF32 -> 51.533333 | AH32: C
A33: KUMAR DAYA SHANKAR | B33: B25ME024 | C33: dskumar@iitbhilai.ac.in | D33: =VLOOKUP(B33, 'ME-Subhashree'!$B$2:$F$56,5) -> 27 | E33: 21 | F33: =0.5*(D33+E33) -> 24 | G33: 7 | H33: 10 | I33: 29 | J33: =G33/4+H33/4+I33/9 -> 7.4722222 | K33: 80 | L33: 150 | N33: =max(L33:M33) -> 150 | O33: 0 | P33: =K33/20+N33/40+O33/20 -> 7.75 | Q33: 6 | R33: 5 | S33: 14 | T33: 10 | U33: 15 | V33: 14 | W33: 20 | X33: 30 | Y33: 28 | Z33: 27 | AA33: 29 | AB33: =SUM(Q33:AA33)/20 -> 9.9 | AC33: 50 | AD33: 50 | AF33: =(AC33+AD33)/40 -> 2.5 | AG33: =F33+J33+P33+AB33+AF33 -> 51.622222 | AH33: C
A34: SHARMA TEJASVI | B34: B25DS038 | C34: tejasvisharma@iitbhilai.ac.in | D34: =VLOOKUP(B34,'DSAI-Vikrant'!$B$2:$F$44,5) -> 18 | E34: 22 | F34: =0.5*(D34+E34) -> 20 | G34: 8 | H34: 7 | I34: 6 | J34: =G34/4+H34/4+I34/9 -> 4.4166667 | K34: 75 | L34: 0 | M34: 175 | N34: =max(L34:M34) -> 175 | O34: 87 | P34: =K34/20+N34/40+O34/20 -> 12.475 | Q34: 7 | S34: 8 | T34: 0 | U34: 14 | V34: 14 | W34: 20 | X34: 0 | Y34: 0 | Z34: 28 | AA34: 30 | AB34: =SUM(Q34:AA34)/20 -> 6.05 | AC34: 30 | AD34: 320 | AF34: =(AC34+AD34)/40 -> 8.75 | AG34: =F34+J34+P34+AB34+AF34 -> 51.691667 | AH34: C
A35: KASHISH KUMARI | B35: B25ME036 | C35: kkumari@iitbhilai.ac.in | D35: =VLOOKUP(B35, 'ME-Subhashree'!$B$2:$F$56,5) -> 28 | E35: 16 | F35: =0.5*(D35+E35) -> 22 | G35: 5 | H35: 2 | I35: 9 | J35: =G35/4+H35/4+I35/9 -> 2.75 | K35: 50 | L35: 125 | N35: =max(L35:M35) -> 125 | O35: 100 | P35: =K35/20+N35/40+O35/20 -> 10.625 | Q35: 6 | R35: 5 | S35: 12 | T35: 12 | U35: 12 | V35: 11 | W35: 20 | X35: 30 | Y35: 28 | AA35: 29 | AB35: =SUM(Q35:AA35)/20 -> 8.25 | AC35: 30 | AD35: 300 | AF35: =(AC35+AD35)/40 -> 8.25 | AG35: =F35+J35+P35+AB35+AF35 -> 51.875 | AH35: C
A36: WRIJESH LUNA | B36: S25MA017 | C36: WRIJESHLUNA@iitbhilai.ac.in | D36: =VLOOKUP(B36, 'MSC-Vikrant'!B12:F23,5) -> 15 | E36: 18 | F36: =0.5*(D36+E36) -> 16.5 | G36: 6 | H36: 10 | I36: 23 | J36: =G36/4+H36/4+I36/9 -> 6.5555556 | K36: 85 | L36: 160 | N36: =max(L36:M36) -> 160 | O36: 92 | P36: =K36/20+N36/40+O36/20 -> 12.85 | Q36: 6 | R36: 6 | S36: 8 | T36: 0 | U36: 14 | V36: 15 | W36: 12 | X36: 28 | Y36: 27 | Z36: 30 | AB36: =SUM(Q36:AA36)/20 -> 7.3 | AC36: 50 | AD36: 300 | AF36: =(AC36+AD36)/40 -> 8.75 | AG36: =F36+J36+P36+AB36+AF36 -> 51.955556 | AH36: C
A37: DEVA PRIYAN S | B37: B25ME025 | C37: dpriyans@iitbhilai.ac.in | D37: =VLOOKUP(B37, 'ME-Subhashree'!$B$2:$F$56,5) -> 32 | E37: 20 | F37: =0.5*(D37+E37) -> 26 | G37: 3 | H37: 2 | I37: 16 | J37: =G37/4+H37/4+I37/9 -> 3.0277778 | K37: 100 | M37: 170 | N37: =max(L37:M37) -> 170 | O37: 0 | P37: =K37/20+N37/40+O37/20 -> 9.25 | Q37: 7 | R37: 1 | S37: 15 | T37: 10 | U37: 15 | V37: 13 | W37: 20 | X37: 0 | Y37: 0 | Z37: 30 | AA37: 27 | AB37: =SUM(Q37:AA37)/20 -> 6.9 | AC37: 0 | AD37: 330 | AF37: =(AC37+AD37)/40 -> 8.25 | AG37: =F37+J37+P37+AB37+AF37 -> 53.427778 | AH37: C
A38: BHANAVATHU PANDU | B38: B25ME019 | C38: bpandu@iitbhilai.ac.in | D38: =VLOOKUP(B38, 'ME-Subhashree'!$B$2:$F$56,5) -> 24 | E38: 15 | F38: =0.5*(D38+E38) -> 19.5 | G38: 2 | H38: 9.5 | I38: 18 | J38: =G38/4+H38/4+I38/9 -> 4.875 | K38: 80 | L38: 155 | N38: =max(L38:M38) -> 155 | O38: 98 | P38: =K38/20+N38/40+O38/20 -> 12.775 | Q38: 5 | R38: 5 | S38: 12 | T38: 12 | U38: 15 | V38: 12 | W38: 20 | X38: 22 | Y38: 17 | Z38: 29 | AA38: 28 | AB38: =SUM(Q38:AA38)/20 -> 8.85 | AC38: 50 | AD38: 250 | AF38: =(AC38+AD38)/40 -> 7.5 | AG38: =F38+J38+P38+AB38+AF38 -> 53.5 | AH38: C
A39: KAMBLE NINAD | B39: B25EE033 | C39: ninadkamble@iitbhilai.ac.in | D39: =VLOOKUP(B39, 'EE-Nitin'!$B$2:$F$57,5) -> 33 | E39: 9 | F39: =0.5*(D39+E39) -> 21 | G39: 2 | H39: 9 | I39: 15 | J39: =G39/4+H39/4+I39/9 -> 4.4166667 | K39: 90 | L39: 95 | N39: =max(L39:M39) -> 95 | O39: 97 | P39: =K39/20+N39/40+O39/20 -> 11.725 | Q39: 5 | R39: 0 | S39: 7 | T39: 6 | U39: 0 | V39: 13.5 | W39: 19.5 | X39: 0 | Y39: 28 | Z39: 29 | AA39: 27 | AB39: =SUM(Q39:AA39)/20 -> 6.75 | AC39: 45 | AD39: 342 | AF39: =(AC39+AD39)/40 -> 9.675 | AG39: =F39+J39+P39+AB39+AF39 -> 53.566667 | AH39: C
A40: TEJASWINEE NAIK | B40: S25MA015 | C40: TEJASWINEENAIK@iitbhilai.ac.in | D40: =VLOOKUP(B40, 'MSC-Vikrant'!B10:F21,5) -> 25 | E40: 10 | F40: =0.5*(D40+E40) -> 17.5 | G40: 11 | H40: 6 | I40: 20 | J40: =G40/4+H40/4+I40/9 -> 6.4722222 | K40: 95 | L40: 160 | N40: =max(L40:M40) -> 160 | O40: 93 | P40: =K40/20+N40/40+O40/20 -> 13.4 | Q40: 7 | R40: 8 | S40: 7 | T40: 0 | U40: 13 | V40: 15 | W40: 13 | X40: 30 | Y40: 27 | Z40: 30 | AB40: =SUM(Q40:AA40)/20 -> 7.5 | AC40: 50 | AD40: 300 | AF40: =(AC40+AD40)/40 -> 8.75 | AG40: =F40+J40+P40+AB40+AF40 -> 53.622222 | AH40: C
...

Sheet Copy of Total-CSL100-Intro_Prog
A1: Name | B1: ID | C1: SIS Login ID | D1: End Sem (60552481) | E1: Mid Sem (58777481) | F1: ExamFinal | G1: Offline Quiz 1 (58279106) | H1: Offline Quiz 2 (59288522) | I1: Offline Quiz 3 (60480072) | J1: QuizFinal | K1: Asg1 | L1: Sliding Characters Game Development in Python (57463646) | M1: Python Clock Assignment (Optional*) (58717731) | N1: Asg 2 | O1: Analyzing call record/history data (59288548) | P1: Asg_Final | Q1: Practice Quiz (57192616) | R1: Practice Quiz - 2 (57710859) | S1: Practice Quiz - 3 (57710877) | T1: Practice Quiz - 4 (57710885) | U1: Practice Sheet 1.1 (57352610) | V1: Practice Sheet 1 (soft copy) (57328669) | W1: Practice Sheet 1.2 + Chapter 2 of IITD Notes (57466219) | X1: Selected Problems from Practice Sheets 2, 3, 4 (57884237) | Y1: Practice Sheet 5 and 6 questions (58107442) | Z1: Practice Sheet - Python (59580084) | AA1: Practice Sheet - Whole Syllabus (60148873) | AB1: PracticeSheetTotal | AC1: Course Project Proposal (59288714) | AD1: Final Project (60057608) | AE1: ProjectFinal | AF1: CourseTotal
A2: Vaibhav Khatri | B2: B24DS035 | C2: vaibhavkh@iitbhilai.ac.in | D2: 36.5 | E2: 29 | F2: =0.5*(D2+E2) -> 32.75 | G2: 15 | H2: 18 | I2: 18 | J2: =G2/4+H2/4+I2/9 -> 10.25 | K2: 80 | L2: 198 | M2: 190 | N2: =max(L2:M2) -> 198 | O2: 95 | P2: =K2/20+N2/40+O2/20 -> 13.7 | Q2: 7 | R2: 9 | S2: 7 | T2: 12 | U2: 15 | V2: 14 | W2: 20 | X2: 29 | Y2: 29 | Z2: 30 | AA2: 30 | AB2: =SUM(Q2:AA2)/20 -> 10.1 | AC2: 50 | AD2: 330 | AE2: =(AC2+AD2)/40 -> 9.5 | AF2: =F2+J2+P2+AB2+AE2 -> 76.3
A3: KILAPARTHI PARVEEN SATYA TEJA | B3: B24EC013 | C3: kilaparthipst@iitbhilai.ac.in | D3: 44 | E3: 30 | F3: =0.5*(D3+E3) -> 37 | G3: 15 | H3: 17 | I3: 24 | J3: =G3/4+H3/4+I3/9 -> 10.666667 | K3: 90 | L3: 190 | M3: 200 | N3: =max(L3:M3) -> 200 | O3: 95 | P3: =K3/20+N3/40+O3/20 -> 14.25 | Q3: 7 | R3: 6 | S3: 8 | T3: 12 | U3: 15 | V3: 15 | W3: 20 | Z3: 30 | AB3: =SUM(Q3:AA3)/20 -> 5.65 | AC3: 50 | AD3: 330 | AE3: =(AC3+AD3)/40 -> 9.5 | AF3: =F3+J3+P3+AB3+AE3 -> 77.066667
A4: SAINI AMAN | B4: B24MT001 | C4: 101624671656031679776 | D4: 45 | E4: 25 | F4: =0.5*(D4+E4) -> 35 | G4: 8 | H4: 18 | I4: 26 | J4: =G4/4+H4/4+I4/9 -> 9.3888889 | K4: 95 | L4: 190 | M4: 190 | N4: =max(L4:M4) -> 190 | O4: 95 | P4: =K4/20+N4/40+O4/20 -> 14.25 | Q4: 6 | T4: 12 | U4: 15 | V4: 15 | W4: 20 | X4: 25 | Y4: 30 | Z4: 30 | AB4: =SUM(Q4:AA4)/20 -> 7.65 | AC4: 50 | AD4: 330 | AE4: =(AC4+AD4)/40 -> 9.5 | AF4: =F4+J4+P4+AB4+AE4 -> 75.788889
A5: Abhinav | B5: B25CS002 | C5: abhinav@iitbhilai.ac.in | D5: =VLOOKUP(B5, 'CSE-Sandeep'!$B$2:$G$61,5) -> 45 | E5: 32 | F5: =0.5*(D5+E5) -> 38.5 | G5: 13 | H5: 13 | I5: 43 | J5: =G5/4+H5/4+I5/9 -> 11.277778 | K5: 100 | L5: 200 | N5: =max(L5:M5) -> 200 | O5: 98 | P5: =K5/20+N5/40+O5/20 -> 14.9 | Q5: 7 | R5: 8 | S5: 15 | T5: 15 | U5: 14 | V5: 15 | W5: 20 | X5: 30 | Y5: 30 | Z5: 3 | AB5: =SUM(Q5:AA5)/20 -> 7.85 | AC5: 40 | AD5: 335 | AE5: =(AC5+AD5)/40 -> 9.375 | AF5: =F5+J5+P5+AB5+AE5 -> 81.902778
A6: ADHIA SOHAM | B6: B25CS003 | C6: adhiasoham@iitbhilai.ac.in | D6: =VLOOKUP(B6, 'CSE-Sandeep'!$B$2:$G$61,5) -> 36 | E6: 31 | F6: =0.5*(D6+E6) -> 33.5 | G6: 17 | H6: 17 | I6: 32.5 | J6: =G6/4+H6/4+I6/9 -> 12.111111 | K6: 100 | L6: 200 | N6: =max(L6:M6) -> 200 | O6: 100 | P6: =K6/20+N6/40+O6/20 -> 15 | Q6: 6 | R6: 8 | S6: 14 | T6: 10 | U6: 15 | V6: 13 | W6: 19 | X6: 30 | Y6: 0 | Z6: 29 | AA6: 30 | AB6: =SUM(Q6:AA6)/20 -> 8.7 | AC6: 50 | AD6: 340 | AE6: =(AC6+AD6)/40 -> 9.75 | AF6: =F6+J6+P6+AB6+AE6 -> 79.061111
A7: ADITYA JAISWAL | B7: B25CS004 | C7: adityajaiswal@iitbhilai.ac.in | D7: =VLOOKUP(B7, 'CSE-Sandeep'!$B$2:$G$61,5) -> 50 | E7: 35 | F7: =0.5*(D7+E7) -> 42.5 | G7: 16 | H7: 16 | I7: 45 | J7: =G7/4+H7/4+I7/9 -> 13 | K7: 90 | L7: 200 | N7: =max(L7:M7) -> 200 | O7: 100 | P7: =K7/20+N7/40+O7/20 -> 14.5 | Q7: 7 | R7: 6 | S7: 14 | T7: 0 | U7: 15 | V7: 15 | W7: 20 | X7: 30 | Y7: 30 | Z7: 30 | AA7: 30 | AB7: =SUM(Q7:AA7)/20 -> 9.85 | AC7: 30 | AD7: 335 | AE7: =(AC7+AD7)/40 -> 9.125 | AF7: =F7+J7+P7+AB7+AE7 -> 88.975
A8: AKSHAT KANSAL | B8: B25CS005 | C8: akshatkansal@iitbhilai.ac.in | D8: =VLOOKUP(B8, 'CSE-Sandeep'!$B$2:$G$61,5) -> 37 | E8: 33 | F8: =0.5*(D8+E8) -> 35 | G8: 11 | H8: 11 | I8: 32 | J8: =G8/4+H8/4+I8/9 -> 9.0555556 | K8: 100 | L8: 200 | N8: =max(L8:M8) -> 200 | O8: 85 | P8: =K8/20+N8/40+O8/20 -> 14.25 | Q8: 6 | R8: 8 | S8: 15 | T8: 10 | U8: 11 | V8: 14 | W8: 20 | X8: 30 | Y8: 30 | Z8: 30 | AB8: =SUM(Q8:AA8)/20 -> 8.7 | AC8: 50 | AD8: 340 | AE8: =(AC8+AD8)/40 -> 9.75 | AF8: =F8+J8+P8+AB8+AE8 -> 76.755556
A9: ANKIT GYEN | B9: B25CS006 | C9: ankitgyen@iitbhilai.ac.in | D9: =VLOOKUP(B9, 'CSE-Sandeep'!$B$2:$G$61,5) -> 46 | E9: 37 | F9: =0.5*(D9+E9) -> 41.5 | G9: 17 | H9: 17 | I9: 37 | J9: =G9/4+H9/4+I9/9 -> 12.611111 | K9: 95 | L9: 200 | N9: =max(L9:M9) -> 200 | P9: =K9/20+N9/40+O9/20 -> 9.75 | Q9: 6 | R9: 7 | S9: 15 | T9: 8 | U9: 15 | V9: 14 | W9: 20 | X9: 30 | Y9: 0 | Z9: 30 | AB9: =SUM(Q9:AA9)/20 -> 7.25 | AC9: 30 | AD9: 340 | AE9: =(AC9+AD9)/40 -> 9.25 | AF9: =F9+J9+P9+AB9+AE9 -> 80.361111
A10: Anugu Raghupathi | B10: B25CS007 | C10: anuguraghu@iitbhilai.ac.in | D10: =VLOOKUP(B10, 'CSE-Sandeep'!$B$2:$G$61,5) -> 24 | E10: 18 | F10: =0.5*(D10+E10) -> 21 | G10: 15 | H10: 15 | I10: 35 | J10: =G10/4+H10/4+I10/9 -> 11.388889 | K10: 85 | L10: 180 | N10: =max(L10:M10) -> 180 | P10: =K10/20+N10/40+O10/20 -> 8.75 | Q10: 5 | R10: 5 | S10: 14 | T10: 10 | U10: 15 | V10: 12 | W10: 20 | X10: 30 | Y10: 24 | Z10: 29 | AA10: 29 | AB10: =SUM(Q10:AA10)/20 -> 9.65 | AC10: 40 | AD10: 340 | AE10: =(AC10+AD10)/40 -> 9.5 | AF10: =F10+J10+P10+AB10+AE10 -> 60.288889
A11: ARYAMAAN SINGH | B11: B25CS008 | C11: aryamaansingh@iitbhilai.ac.in | D11: =VLOOKUP(B11, 'CSE-Sandeep'!$B$2:$G$61,5) -> 47 | E11: 33 | F11: =0.5*(D11+E11) -> 40 | G11: 11 | H11: 11 | I11: 35.5 | J11: =G11/4+H11/4+I11/9 -> 9.4444444 | K11: 95 | L11: 190 | N11: =max(L11:M11) -> 190 | O11: 92 | P11: =K11/20+N11/40+O11/20 -> 14.1 | Q11: 6 | R11: 8 | S11: 14 | T11: 10 | U11: 15 | V11: 14 | W11: 20 | X11: 30 | Y11: 30 | Z11: 30 | AB11: =SUM(Q11:AA11)/20 -> 8.85 | AC11: 50 | AD11: 330 | AE11: =(AC11+AD11)/40 -> 9.5 | AF11: =F11+J11+P11+AB11+AE11 -> 81.894444
A12: ARYAN DESHMUKH | B12: B25CS009 | C12: aryanmanish@iitbhilai.ac.in | D12: =VLOOKUP(B12, 'CSE-Sandeep'!$B$2:$G$61,5) -> 40 | E12: 35 | F12: =0.5*(D12+E12) -> 37.5 | G12: 16 | H12: 16 | I12: 45 | J12: =G12/4+H12/4+I12/9 -> 13 | K12: 95 | L12: 170 | M12: 195 | N12: =max(L12:M12) -> 195 | O12: 95 | P12: =K12/20+N12/40+O12/20 -> 14.375 | Q12: 7 | R12: 5 | S12: 14 | T12: 8 | U12: 15 | V12: 14 | W12: 20 | X12: 30 | Y12: 30 | Z12: 30 | AA12: 30 | AB12: =SUM(Q12:AA12)/20 -> 10.15 | AC12: 50 | AD12: 340 | AE12: =(AC12+AD12)/40 -> 9.75 | AF12: =F12+J12+P12+AB12+AE12 -> 84.775
A13: ARYAVEER SINGH RAWAT | B13: B25CS010 | C13: aryaveersingh@iitbhilai.ac.in | D13: =VLOOKUP(B13, 'CSE-Sandeep'!$B$2:$G$61,5) -> 51 | E13: 40 | F13: =0.5*(D13+E13) -> 45.5 | G13: 19 | H13: 19 | I13: 40 | J13: =G13/4+H13/4+I13/9 -> 13.944444 | K13: 100 | L13: 190 | N13: =max(L13:M13) -> 190 | O13: 85 | P13: =K13/20+N13/40+O13/20 -> 14 | Q13: 7 | R13: 9 | S13: 15 | T13: 11 | U13: 15 | V13: 15 | W13: 20 | X13: 30 | Y13: 30 | Z13: 30 | AA13: 30 | AB13: =SUM(Q13:AA13)/20 -> 10.6 | AC13: 50 | AD13: 335 | AE13: =(AC13+AD13)/40 -> 9.625 | AF13: =F13+J13+P13+AB13+AE13 -> 93.669444
A14: BHARGAV SHARMA | B14: B25CS011 | C14: bhargavsharma@iitbhilai.ac.in | D14: =VLOOKUP(B14, 'CSE-Sandeep'!$B$2:$G$61,5) -> 46 | E14: 37 | F14: =0.5*(D14+E14) -> 41.5 | G14: 19 | H14: 19 | I14: 45 | J14: =G14/4+H14/4+I14/9 -> 14.5 | K14: 100 | L14: 200 | N14: =max(L14:M14) -> 200 | O14: 95 | P14: =K14/20+N14/40+O14/20 -> 14.75 | Q14: 7 | R14: 9 | S14: 15 | T14: 11 | U14: 15 | V14: 14 | W14: 20 | X14: 30 | Y14: 30 | Z14: 30 | AA14: 30 | AB14: =SUM(Q14:AA14)/20 -> 10.55 | AC14: 30 | AD14: 340 | AE14: =(AC14+AD14)/40 -> 9.25 | AF14: =F14+J14+P14+AB14+AE14 -> 90.55
A15: KHANDELWAL BHAVYA SANTKUMAR | B15: B25CS012 | C15: bhavyasantku@iitbhilai.ac.in | D15: =VLOOKUP(B15, 'CSE-Sandeep'!$B$2:$G$61,5) -> 50 | E15: 35 | F15: =0.5*(D15+E15) -> 42.5 | G15: 17 | H15: 17 | I15: 34 | J15: =G15/4+H15/4+I15/9 -> 12.277778 | K15: 76 | L15: 190 | N15: =max(L15:M15) -> 190 | O15: 89 | P15: =K15/20+N15/40+O15/20 -> 13 | Q15: 7 | R15: 7 | S15: 14 | T15: 0 | U15: 14 | V15: 14 | W15: 0 | X15: 30 | Y15: 26 | Z15: 29 | AA15: 28 | AB15: =SUM(Q15:AA15)/20 -> 8.45 | AC15: 30 | AD15: 340 | AE15: =(AC15+AD15)/40 -> 9.25 | AF15: =F15+J15+P15+AB15+AE15 -> 85.477778
A16: NITEESH BODA | B16: B25CS013 | C16: bodaniteesh@iitbhilai.ac.in | D16: =VLOOKUP(B16, 'CSE-Sandeep'!$B$2:$G$61,5) -> 38 | E16: 19 | F16: =0.5*(D16+E16) -> 28.5 | G16: 6 | H16: 6 | I16: 35 | J16: =G16/4+H16/4+I16/9 -> 6.8888889 | K16: 90 | L16: 180 | N16: =max(L16:M16) -> 180 | O16: 89 | P16: =K16/20+N16/40+O16/20 -> 13.45 | Q16: 7 | R16: 2 | S16: 15 | T16: 10 | U16: 14 | V16: 14 | W16: 20 | X16: 30 | Y16: 30 | Z16: 28 | AA16: 28 | AB16: =SUM(Q16:AA16)/20 -> 9.9 | AC16: 30 | AD16: 335 | AE16: =(AC16+AD16)/40 -> 9.125 | AF16: =F16+J16+P16+AB16+AE16 -> 67.863889
A17: DIPA SAHA | B17: B25CS014 | C17: dipasaha@iitbhilai.ac.in | D17: =VLOOKUP(B17, 'CSE-Sandeep'!$B$2:$G$61,5) -> 23 | E17: 2 | F17: =0.5*(D17+E17) -> 12.5 | G17: 7 | H17: 7 | I17: 19 | J17: =G17/4+H17/4+I17/9 -> 5.6111111 | K17: 90 | L17: 180 | N17: =max(L17:M17) -> 180 | O17: 95 | P17: =K17/20+N17/40+O17/20 -> 13.75 | Q17: 6 | R17: 7 | S17: 14 | T17: 0 | U17: 14 | V17: 14 | W17: 20 | X17: 30 | Y17: 30 | Z17: 28 | AA17: 28 | AB17: =SUM(Q17:AA17)/20 -> 9.55 | AC17: 50 | AD17: 340 | AE17: =(AC17+AD17)/40 -> 9.75 | AF17: =F17+J17+P17+AB17+AE17 -> 51.161111
A18: DISHANK VERMA | B18: B25CS015 | C18: dishankverma@iitbhilai.ac.in | D18: =VLOOKUP(B18, 'CSE-Sandeep'!$B$2:$G$61,5) -> 21 | E18: 11 | F18: =0.5*(D18+E18) -> 16 | G18: 6 | H18: 6 | I18: 18 | J18: =G18/4+H18/4+I18/9 -> 5 | K18: 87 | L18: 180 | N18: =max(L18:M18) -> 180 | O18: 85 | P18: =K18/20+N18/40+O18/20 -> 13.1 | Q18: 5 | R18: 4 | S18: 15 | T18: 5 | U18: 5 | V18: 14 | W18: 0 | X18: 30 | Z18: 28 | AB18: =SUM(Q18:AA18)/20 -> 5.3 | AC18: 50 | AD18: 330 | AE18: =(AC18+AD18)/40 -> 9.5 | AF18: =F18+J18+P18+AB18+AE18 -> 48.9
A19: DIVYANSH KORI | B19: B25CS016 | C19: divyanshkori@iitbhilai.ac.in | D19: =VLOOKUP(B19, 'CSE-Sandeep'!$B$2:$G$61,5) -> 54 | E19: 36 | F19: =0.5*(D19+E19) -> 45 | G19: 20 | H19: 20 | I19: 36 | J19: =G19/4+H19/4+I19/9 -> 14 | K19: 100 | L19: 180 | N19: =max(L19:M19) -> 180 | O19: 100 | P19: =K19/20+N19/40+O19/20 -> 14.5 | Q19: 7 | R19: 9 | S19: 14 | T19: 8 | U19: 15 | V19: 14 | W19: 20 | X19: 30 | Y19: 21 | Z19: 30 | AA19: 30 | AB19: =SUM(Q19:AA19)/20 -> 9.9 | AC19: 50 | AD19: 340 | AE19: =(AC19+AD19)/40 -> 9.75 | AF19: =F19+J19+P19+AB19+AE19 -> 93.15
A20: HUSEN FARUKH | B20: B25CS017 | C20: farukhhusen@iitbhilai.ac.in | D20: =VLOOKUP(B20, 'CSE-Sandeep'!$B$2:$G$61,5) -> 41 | E20: 28 | F20: =0.5*(D20+E20) -> 34.5 | G20: 8 | H20: 8 | I20: 29 | J20: =G20/4+H20/4+I20/9 -> 7.2222222 | K20: 80 | L20: 180 | N20: =max(L20:M20) -> 180 | O20: 91 | P20: =K20/20+N20/40+O20/20 -> 13.05 | Q20: 6 | R20: 5 | S20: 14 | T20: 8 | U20: 13 | V20: 14 | W20: 19 | X20: 30 | Z20: 28 | AA20: 28 | AB20: =SUM(Q20:AA20)/20 -> 8.25 | AC20: 30 | AD20: 330 | AE20: =(AC20+AD20)/40 -> 9 | AF20: =F20+J20+P20+AB20+AE20 -> 72.022222
A21: GANDI NAVYA | B21: B25CS018 | C21: gandinavya@iitbhilai.ac.in | D21: =VLOOKUP(B21, 'CSE-Sandeep'!$B$2:$G$61,5) -> 43 | E21: 20 | F21: =0.5*(D21+E21) -> 31.5 | G21: 10 | H21: 10 | I21: 20.5 | J21: =G21/4+H21/4+I21/9 -> 7.2777778 | K21: 80 | L21: 180 | N21: =max(L21:M21) -> 180 | O21: 98 | P21: =K21/20+N21/40+O21/20 -> 13.4 | Q21: 7 | R21: 6 | S21: 14 | T21: 8 | U21: 15 | V21: 9 | W21: 20 | X21: 30 | Y21: 18 | Z21: 28 | AB21: =SUM(Q21:AA21)/20 -> 7.75 | AC21: 40 | AD21: 340 | AE21: =(AC21+AD21)/40 -> 9.5 | AF21: =F21+J21+P21+AB21+AE21 -> 69.427778
A22: GEGGELAPALLY VAISHNAVI | B22: B25CS019 | C22: geggelapallyv@iitbhilai.ac.in | D22: =VLOOKUP(B22, 'CSE-Sandeep'!$B$2:$G$61,5) -> 43 | E22: 37 | F22: =0.5*(D22+E22) -> 40 | G22: 12 | H22: 12 | I22: 25 | J22: =G22/4+H22/4+I22/9 -> 8.7777778 | K22: 90 | L22: 190 | N22: =max(L22:M22) -> 190 | O22: 90 | P22: =K22/20+N22/40+O22/20 -> 13.75 | Q22: 7 | R22: 8 | S22: 14 | T22: 12 | U22: 15 | V22: 14 | W22: 20 | X22: 30 | Y22: 20 | Z22: 30 | AA22: 30 | AB22: =SUM(Q22:AA22)/20 -> 10 | AD22: 340 | AE22: =(AC22+AD22)/40 -> 8.5 | AF22: =F22+J22+P22+AB22+AE22 -> 81.027778
A23: HARSH | B23: B25CS020 | C23: harshr@iitbhilai.ac.in | D23: =VLOOKUP(B23, 'CSE-Sandeep'!$B$2:$G$61,5) -> 37 | E23: 28 | F23: =0.5*(D23+E23) -> 32.5 | G23: 14 | H23: 14 | I23: 40 | J23: =G23/4+H23/4+I23/9 -> 11.444444 | K23: 95 | L23: 190 | N23: =max(L23:M23) -> 190 | O23: 100 | P23: =K23/20+N23/40+O23/20 -> 14.5 | Q23: 6 | R23: 7 | S23: 15 | T23: 10 | U23: 15 | V23: 14 | W23: 17 | X23: 30 | Y23: 20 | Z23: 30 | AA23: 30 | AB23: =SUM(Q23:AA23)/20 -> 9.7 | AC23: 50 | AD23: 330 | AE23: =(AC23+AD23)/40 -> 9.5 | AF23: =F23+J23+P23+AB23+AE23 -> 77.644444
